distributed.nanny - INFO -         Start Nanny at: 'tcp://198.202.101.9:46177'
distributed.nanny - INFO -         Start Nanny at: 'tcp://198.202.101.9:37681'
distributed.nanny - INFO -         Start Nanny at: 'tcp://198.202.101.9:40871'
distributed.nanny - INFO -         Start Nanny at: 'tcp://198.202.101.9:33343'
distributed.nanny - INFO -         Start Nanny at: 'tcp://198.202.101.9:34255'
distributed.nanny - INFO -         Start Nanny at: 'tcp://198.202.101.9:37885'
distributed.nanny - INFO -         Start Nanny at: 'tcp://198.202.101.9:38359'
distributed.nanny - INFO -         Start Nanny at: 'tcp://198.202.101.9:40777'
distributed.nanny - INFO -         Start Nanny at: 'tcp://198.202.101.9:43041'
distributed.nanny - INFO -         Start Nanny at: 'tcp://198.202.101.9:37753'
distributed.nanny - INFO -         Start Nanny at: 'tcp://198.202.101.9:38257'
distributed.nanny - INFO -         Start Nanny at: 'tcp://198.202.101.9:33295'
distributed.nanny - INFO -         Start Nanny at: 'tcp://198.202.101.9:38683'
distributed.nanny - INFO -         Start Nanny at: 'tcp://198.202.101.9:40779'
distributed.nanny - INFO -         Start Nanny at: 'tcp://198.202.101.9:35589'
distributed.nanny - INFO -         Start Nanny at: 'tcp://198.202.101.9:37915'
distributed.nanny - INFO -         Start Nanny at: 'tcp://198.202.101.9:46809'
distributed.nanny - INFO -         Start Nanny at: 'tcp://198.202.101.9:43697'
distributed.nanny - INFO -         Start Nanny at: 'tcp://198.202.101.9:39871'
distributed.nanny - INFO -         Start Nanny at: 'tcp://198.202.101.9:41415'
distributed.nanny - INFO -         Start Nanny at: 'tcp://198.202.101.9:36221'
distributed.nanny - INFO -         Start Nanny at: 'tcp://198.202.101.9:34677'
distributed.nanny - INFO -         Start Nanny at: 'tcp://198.202.101.9:37949'
distributed.nanny - INFO -         Start Nanny at: 'tcp://198.202.101.9:41409'
distributed.nanny - INFO -         Start Nanny at: 'tcp://198.202.101.9:42267'
distributed.nanny - INFO -         Start Nanny at: 'tcp://198.202.101.9:37829'
distributed.nanny - INFO -         Start Nanny at: 'tcp://198.202.101.9:43467'
distributed.nanny - INFO -         Start Nanny at: 'tcp://198.202.101.9:39317'
distributed.nanny - INFO -         Start Nanny at: 'tcp://198.202.101.9:45887'
distributed.nanny - INFO -         Start Nanny at: 'tcp://198.202.101.9:37217'
distributed.nanny - INFO -         Start Nanny at: 'tcp://198.202.101.9:34455'
distributed.nanny - INFO -         Start Nanny at: 'tcp://198.202.101.9:33429'
distributed.nanny - INFO -         Start Nanny at: 'tcp://198.202.101.9:40931'
distributed.nanny - INFO -         Start Nanny at: 'tcp://198.202.101.9:34097'
distributed.nanny - INFO -         Start Nanny at: 'tcp://198.202.101.9:33897'
distributed.nanny - INFO -         Start Nanny at: 'tcp://198.202.101.9:34011'
distributed.nanny - INFO -         Start Nanny at: 'tcp://198.202.101.9:38743'
distributed.nanny - INFO -         Start Nanny at: 'tcp://198.202.101.9:43363'
distributed.nanny - INFO -         Start Nanny at: 'tcp://198.202.101.9:37215'
distributed.nanny - INFO -         Start Nanny at: 'tcp://198.202.101.9:33537'
distributed.nanny - INFO -         Start Nanny at: 'tcp://198.202.101.9:37607'
distributed.nanny - INFO -         Start Nanny at: 'tcp://198.202.101.9:46541'
distributed.nanny - INFO -         Start Nanny at: 'tcp://198.202.101.9:41515'
distributed.nanny - INFO -         Start Nanny at: 'tcp://198.202.101.9:42913'
distributed.nanny - INFO -         Start Nanny at: 'tcp://198.202.101.9:44913'
distributed.nanny - INFO -         Start Nanny at: 'tcp://198.202.101.9:37705'
distributed.nanny - INFO -         Start Nanny at: 'tcp://198.202.101.9:36323'
distributed.nanny - INFO -         Start Nanny at: 'tcp://198.202.101.9:41137'
distributed.nanny - INFO -         Start Nanny at: 'tcp://198.202.101.9:42179'
distributed.nanny - INFO -         Start Nanny at: 'tcp://198.202.101.9:38515'
/home/ntolley/anaconda3/envs/sbi/lib/python3.8/contextlib.py:120: UserWarning: Creating scratch directories is taking a surprisingly long time. This is often due to running workers on a network file system. Consider specifying a local-directory to point workers to write scratch data to a local disk.
  next(self.gen)
distributed.worker - INFO -       Start worker at:  tcp://198.202.101.9:45597
/home/ntolley/anaconda3/envs/sbi/lib/python3.8/contextlib.py:120: UserWarning: Creating scratch directories is taking a surprisingly long time. This is often due to running workers on a network file system. Consider specifying a local-directory to point workers to write scratch data to a local disk.
  next(self.gen)
distributed.worker - INFO -       Start worker at:  tcp://198.202.101.9:38601
/home/ntolley/anaconda3/envs/sbi/lib/python3.8/contextlib.py:120: UserWarning: Creating scratch directories is taking a surprisingly long time. This is often due to running workers on a network file system. Consider specifying a local-directory to point workers to write scratch data to a local disk.
  next(self.gen)
distributed.worker - INFO -       Start worker at:  tcp://198.202.101.9:39333
distributed.worker - INFO -          Listening to:  tcp://198.202.101.9:45597
/home/ntolley/anaconda3/envs/sbi/lib/python3.8/contextlib.py:120: UserWarning: Creating scratch directories is taking a surprisingly long time. This is often due to running workers on a network file system. Consider specifying a local-directory to point workers to write scratch data to a local disk.
  next(self.gen)
distributed.worker - INFO -       Start worker at:  tcp://198.202.101.9:33319
distributed.worker - INFO -          Listening to:  tcp://198.202.101.9:38601
/home/ntolley/anaconda3/envs/sbi/lib/python3.8/contextlib.py:120: UserWarning: Creating scratch directories is taking a surprisingly long time. This is often due to running workers on a network file system. Consider specifying a local-directory to point workers to write scratch data to a local disk.
  next(self.gen)
distributed.worker - INFO -       Start worker at:  tcp://198.202.101.9:36945
distributed.worker - INFO -          Listening to:  tcp://198.202.101.9:39333
distributed.worker - INFO -          dashboard at:        198.202.101.9:38945
/home/ntolley/anaconda3/envs/sbi/lib/python3.8/contextlib.py:120: UserWarning: Creating scratch directories is taking a surprisingly long time. This is often due to running workers on a network file system. Consider specifying a local-directory to point workers to write scratch data to a local disk.
  next(self.gen)
distributed.worker - INFO -       Start worker at:  tcp://198.202.101.9:34995
/home/ntolley/anaconda3/envs/sbi/lib/python3.8/contextlib.py:120: UserWarning: Creating scratch directories is taking a surprisingly long time. This is often due to running workers on a network file system. Consider specifying a local-directory to point workers to write scratch data to a local disk.
  next(self.gen)
distributed.worker - INFO -       Start worker at:  tcp://198.202.101.9:32867
/home/ntolley/anaconda3/envs/sbi/lib/python3.8/contextlib.py:120: UserWarning: Creating scratch directories is taking a surprisingly long time. This is often due to running workers on a network file system. Consider specifying a local-directory to point workers to write scratch data to a local disk.
  next(self.gen)
distributed.worker - INFO -       Start worker at:  tcp://198.202.101.9:42731
distributed.worker - INFO -          dashboard at:        198.202.101.9:42713
distributed.worker - INFO - Waiting to connect to: tcp://198.202.103.184:34547
distributed.worker - INFO -          dashboard at:        198.202.101.9:34557
distributed.worker - INFO -          Listening to:  tcp://198.202.101.9:32867
distributed.worker - INFO - -------------------------------------------------
distributed.worker - INFO - Waiting to connect to: tcp://198.202.103.184:34547
distributed.worker - INFO -          Listening to:  tcp://198.202.101.9:42731
distributed.worker - INFO - Waiting to connect to: tcp://198.202.103.184:34547
/home/ntolley/anaconda3/envs/sbi/lib/python3.8/contextlib.py:120: UserWarning: Creating scratch directories is taking a surprisingly long time. This is often due to running workers on a network file system. Consider specifying a local-directory to point workers to write scratch data to a local disk.
  next(self.gen)
distributed.worker - INFO -       Start worker at:  tcp://198.202.101.9:38135
distributed.worker - INFO -          dashboard at:        198.202.101.9:45551
distributed.worker - INFO -          Listening to:  tcp://198.202.101.9:33319
distributed.worker - INFO - -------------------------------------------------
distributed.worker - INFO - -------------------------------------------------
distributed.worker - INFO -          dashboard at:        198.202.101.9:41743
distributed.worker - INFO -          Listening to:  tcp://198.202.101.9:36945
distributed.worker - INFO - Waiting to connect to: tcp://198.202.103.184:34547
distributed.worker - INFO -          Listening to:  tcp://198.202.101.9:38135
distributed.worker - INFO -          Listening to:  tcp://198.202.101.9:34995
distributed.worker - INFO -               Threads:                          1
distributed.worker - INFO -          dashboard at:        198.202.101.9:42213
distributed.worker - INFO - Waiting to connect to: tcp://198.202.103.184:34547
distributed.worker - INFO - -------------------------------------------------
distributed.worker - INFO -          dashboard at:        198.202.101.9:42727
distributed.worker - INFO -               Threads:                          1
distributed.worker - INFO - -------------------------------------------------
distributed.worker - INFO -          dashboard at:        198.202.101.9:44415
distributed.worker - INFO - Waiting to connect to: tcp://198.202.103.184:34547
distributed.worker - INFO -               Threads:                          1
distributed.worker - INFO -                Memory:                    4.00 GB
distributed.worker - INFO -          dashboard at:        198.202.101.9:45225
distributed.worker - INFO - Waiting to connect to: tcp://198.202.103.184:34547
distributed.worker - INFO -                Memory:                    4.00 GB
distributed.worker - INFO - -------------------------------------------------
distributed.worker - INFO - Waiting to connect to: tcp://198.202.103.184:34547
distributed.worker - INFO -       Local Directory: /home/ntolley/Jones_Lab/sbi_hnn_github/code/ERP/dask-worker-space/dask-worker-space/worker-42k3ohu1
distributed.worker - INFO - -------------------------------------------------
distributed.worker - INFO -                Memory:                    4.00 GB
distributed.worker - INFO - Waiting to connect to: tcp://198.202.103.184:34547
distributed.worker - INFO -               Threads:                          1
distributed.worker - INFO -       Local Directory: /home/ntolley/Jones_Lab/sbi_hnn_github/code/ERP/dask-worker-space/dask-worker-space/worker-7g9e2hgp
distributed.worker - INFO - -------------------------------------------------
distributed.worker - INFO -               Threads:                          1
distributed.worker - INFO -       Local Directory: /home/ntolley/Jones_Lab/sbi_hnn_github/code/ERP/dask-worker-space/dask-worker-space/worker-_9ey0qr0
distributed.worker - INFO - -------------------------------------------------
distributed.worker - INFO -                Memory:                    4.00 GB
distributed.worker - INFO -               Threads:                          1
distributed.worker - INFO -                Memory:                    4.00 GB
distributed.worker - INFO - -------------------------------------------------
distributed.worker - INFO -       Local Directory: /home/ntolley/Jones_Lab/sbi_hnn_github/code/ERP/dask-worker-space/dask-worker-space/worker-g_stzl7d
distributed.worker - INFO -               Threads:                          1
distributed.worker - INFO -       Local Directory: /home/ntolley/Jones_Lab/sbi_hnn_github/code/ERP/dask-worker-space/dask-worker-space/worker-s99s8dbh
distributed.worker - INFO -               Threads:                          1
distributed.worker - INFO -                Memory:                    4.00 GB
distributed.worker - INFO - -------------------------------------------------
distributed.worker - INFO -               Threads:                          1
distributed.worker - INFO -       Local Directory: /home/ntolley/Jones_Lab/sbi_hnn_github/code/ERP/dask-worker-space/dask-worker-space/worker-_ykva1ca
distributed.worker - INFO -                Memory:                    4.00 GB
distributed.worker - INFO -                Memory:                    4.00 GB
distributed.worker - INFO - -------------------------------------------------
distributed.worker - INFO - -------------------------------------------------
distributed.worker - INFO -                Memory:                    4.00 GB
distributed.worker - INFO - -------------------------------------------------
distributed.worker - INFO -       Local Directory: /home/ntolley/Jones_Lab/sbi_hnn_github/code/ERP/dask-worker-space/dask-worker-space/worker-b4_bmjfo
distributed.worker - INFO -       Local Directory: /home/ntolley/Jones_Lab/sbi_hnn_github/code/ERP/dask-worker-space/dask-worker-space/worker-k22_dqqn
distributed.worker - INFO -       Local Directory: /home/ntolley/Jones_Lab/sbi_hnn_github/code/ERP/dask-worker-space/dask-worker-space/worker-8bkjpf9n
distributed.worker - INFO - -------------------------------------------------
distributed.worker - INFO - -------------------------------------------------
distributed.worker - INFO - -------------------------------------------------
distributed.worker - INFO - -------------------------------------------------
/home/ntolley/anaconda3/envs/sbi/lib/python3.8/contextlib.py:120: UserWarning: Creating scratch directories is taking a surprisingly long time. This is often due to running workers on a network file system. Consider specifying a local-directory to point workers to write scratch data to a local disk.
  next(self.gen)
distributed.worker - INFO -       Start worker at:  tcp://198.202.101.9:43323
distributed.worker - INFO -          Listening to:  tcp://198.202.101.9:43323
distributed.worker - INFO -          dashboard at:        198.202.101.9:39575
distributed.worker - INFO - Waiting to connect to: tcp://198.202.103.184:34547
distributed.worker - INFO - -------------------------------------------------
distributed.worker - INFO -               Threads:                          1
distributed.worker - INFO -                Memory:                    4.00 GB
distributed.worker - INFO -       Local Directory: /home/ntolley/Jones_Lab/sbi_hnn_github/code/ERP/dask-worker-space/dask-worker-space/worker-q22eudiw
distributed.worker - INFO - -------------------------------------------------
/home/ntolley/anaconda3/envs/sbi/lib/python3.8/contextlib.py:120: UserWarning: Creating scratch directories is taking a surprisingly long time. This is often due to running workers on a network file system. Consider specifying a local-directory to point workers to write scratch data to a local disk.
  next(self.gen)
distributed.worker - INFO -       Start worker at:  tcp://198.202.101.9:35579
distributed.worker - INFO -          Listening to:  tcp://198.202.101.9:35579
distributed.worker - INFO -          dashboard at:        198.202.101.9:42107
distributed.worker - INFO - Waiting to connect to: tcp://198.202.103.184:34547
distributed.worker - INFO - -------------------------------------------------
distributed.worker - INFO -               Threads:                          1
distributed.worker - INFO -                Memory:                    4.00 GB
distributed.worker - INFO -       Local Directory: /home/ntolley/Jones_Lab/sbi_hnn_github/code/ERP/dask-worker-space/dask-worker-space/worker-jx7kpj2b
distributed.worker - INFO - -------------------------------------------------
/home/ntolley/anaconda3/envs/sbi/lib/python3.8/contextlib.py:120: UserWarning: Creating scratch directories is taking a surprisingly long time. This is often due to running workers on a network file system. Consider specifying a local-directory to point workers to write scratch data to a local disk.
  next(self.gen)
distributed.worker - INFO -       Start worker at:  tcp://198.202.101.9:39931
distributed.worker - INFO -          Listening to:  tcp://198.202.101.9:39931
distributed.worker - INFO -          dashboard at:        198.202.101.9:45965
distributed.worker - INFO - Waiting to connect to: tcp://198.202.103.184:34547
distributed.worker - INFO - -------------------------------------------------
distributed.worker - INFO -               Threads:                          1
distributed.worker - INFO -                Memory:                    4.00 GB
distributed.worker - INFO -       Local Directory: /home/ntolley/Jones_Lab/sbi_hnn_github/code/ERP/dask-worker-space/dask-worker-space/worker-3ebi55rz
distributed.worker - INFO - -------------------------------------------------
/home/ntolley/anaconda3/envs/sbi/lib/python3.8/contextlib.py:120: UserWarning: Creating scratch directories is taking a surprisingly long time. This is often due to running workers on a network file system. Consider specifying a local-directory to point workers to write scratch data to a local disk.
  next(self.gen)
distributed.worker - INFO -       Start worker at:  tcp://198.202.101.9:46179
distributed.worker - INFO -          Listening to:  tcp://198.202.101.9:46179
distributed.worker - INFO -          dashboard at:        198.202.101.9:35557
distributed.worker - INFO - Waiting to connect to: tcp://198.202.103.184:34547
distributed.worker - INFO - -------------------------------------------------
distributed.worker - INFO -               Threads:                          1
distributed.worker - INFO -                Memory:                    4.00 GB
distributed.worker - INFO -       Local Directory: /home/ntolley/Jones_Lab/sbi_hnn_github/code/ERP/dask-worker-space/dask-worker-space/worker-j7pwuuvu
distributed.worker - INFO - -------------------------------------------------
/home/ntolley/anaconda3/envs/sbi/lib/python3.8/contextlib.py:120: UserWarning: Creating scratch directories is taking a surprisingly long time. This is often due to running workers on a network file system. Consider specifying a local-directory to point workers to write scratch data to a local disk.
  next(self.gen)
distributed.worker - INFO -       Start worker at:  tcp://198.202.101.9:34801
distributed.worker - INFO -          Listening to:  tcp://198.202.101.9:34801
distributed.worker - INFO -          dashboard at:        198.202.101.9:42315
distributed.worker - INFO - Waiting to connect to: tcp://198.202.103.184:34547
distributed.worker - INFO - -------------------------------------------------
distributed.worker - INFO -               Threads:                          1
distributed.worker - INFO -                Memory:                    4.00 GB
distributed.worker - INFO -       Local Directory: /home/ntolley/Jones_Lab/sbi_hnn_github/code/ERP/dask-worker-space/dask-worker-space/worker-8o79ptbb
distributed.worker - INFO - -------------------------------------------------
/home/ntolley/anaconda3/envs/sbi/lib/python3.8/contextlib.py:120: UserWarning: Creating scratch directories is taking a surprisingly long time. This is often due to running workers on a network file system. Consider specifying a local-directory to point workers to write scratch data to a local disk.
  next(self.gen)
distributed.worker - INFO -       Start worker at:  tcp://198.202.101.9:40983
distributed.worker - INFO -          Listening to:  tcp://198.202.101.9:40983
distributed.worker - INFO -          dashboard at:        198.202.101.9:39471
distributed.worker - INFO - Waiting to connect to: tcp://198.202.103.184:34547
distributed.worker - INFO - -------------------------------------------------
distributed.worker - INFO -               Threads:                          1
distributed.worker - INFO -                Memory:                    4.00 GB
distributed.worker - INFO -       Local Directory: /home/ntolley/Jones_Lab/sbi_hnn_github/code/ERP/dask-worker-space/dask-worker-space/worker-hud10zl5
distributed.worker - INFO - -------------------------------------------------
/home/ntolley/anaconda3/envs/sbi/lib/python3.8/contextlib.py:120: UserWarning: Creating scratch directories is taking a surprisingly long time. This is often due to running workers on a network file system. Consider specifying a local-directory to point workers to write scratch data to a local disk.
  next(self.gen)
distributed.worker - INFO -       Start worker at:  tcp://198.202.101.9:36043
distributed.worker - INFO -          Listening to:  tcp://198.202.101.9:36043
distributed.worker - INFO -          dashboard at:        198.202.101.9:44207
distributed.worker - INFO - Waiting to connect to: tcp://198.202.103.184:34547
distributed.worker - INFO - -------------------------------------------------
distributed.worker - INFO -               Threads:                          1
distributed.worker - INFO -                Memory:                    4.00 GB
distributed.worker - INFO -       Local Directory: /home/ntolley/Jones_Lab/sbi_hnn_github/code/ERP/dask-worker-space/dask-worker-space/worker-0tltxlb4
distributed.worker - INFO - -------------------------------------------------
/home/ntolley/anaconda3/envs/sbi/lib/python3.8/contextlib.py:120: UserWarning: Creating scratch directories is taking a surprisingly long time. This is often due to running workers on a network file system. Consider specifying a local-directory to point workers to write scratch data to a local disk.
  next(self.gen)
distributed.worker - INFO -       Start worker at:  tcp://198.202.101.9:32945
distributed.worker - INFO -          Listening to:  tcp://198.202.101.9:32945
distributed.worker - INFO -          dashboard at:        198.202.101.9:37069
distributed.worker - INFO - Waiting to connect to: tcp://198.202.103.184:34547
distributed.worker - INFO - -------------------------------------------------
distributed.worker - INFO -               Threads:                          1
distributed.worker - INFO -                Memory:                    4.00 GB
distributed.worker - INFO -       Local Directory: /home/ntolley/Jones_Lab/sbi_hnn_github/code/ERP/dask-worker-space/dask-worker-space/worker-dbe7q4gj
distributed.worker - INFO - -------------------------------------------------
/home/ntolley/anaconda3/envs/sbi/lib/python3.8/contextlib.py:120: UserWarning: Creating scratch directories is taking a surprisingly long time. This is often due to running workers on a network file system. Consider specifying a local-directory to point workers to write scratch data to a local disk.
  next(self.gen)
distributed.worker - INFO -       Start worker at:  tcp://198.202.101.9:35459
distributed.worker - INFO -          Listening to:  tcp://198.202.101.9:35459
distributed.worker - INFO -          dashboard at:        198.202.101.9:40149
distributed.worker - INFO - Waiting to connect to: tcp://198.202.103.184:34547
distributed.worker - INFO - -------------------------------------------------
distributed.worker - INFO -               Threads:                          1
distributed.worker - INFO -                Memory:                    4.00 GB
distributed.worker - INFO -       Local Directory: /home/ntolley/Jones_Lab/sbi_hnn_github/code/ERP/dask-worker-space/dask-worker-space/worker-_4bz7lor
distributed.worker - INFO - -------------------------------------------------
/home/ntolley/anaconda3/envs/sbi/lib/python3.8/contextlib.py:120: UserWarning: Creating scratch directories is taking a surprisingly long time. This is often due to running workers on a network file system. Consider specifying a local-directory to point workers to write scratch data to a local disk.
  next(self.gen)
distributed.worker - INFO -       Start worker at:  tcp://198.202.101.9:42739
distributed.worker - INFO -          Listening to:  tcp://198.202.101.9:42739
distributed.worker - INFO -          dashboard at:        198.202.101.9:39089
distributed.worker - INFO - Waiting to connect to: tcp://198.202.103.184:34547
distributed.worker - INFO - -------------------------------------------------
distributed.worker - INFO -               Threads:                          1
distributed.worker - INFO -                Memory:                    4.00 GB
distributed.worker - INFO -       Local Directory: /home/ntolley/Jones_Lab/sbi_hnn_github/code/ERP/dask-worker-space/dask-worker-space/worker-hvwyjdy8
distributed.worker - INFO - -------------------------------------------------
/home/ntolley/anaconda3/envs/sbi/lib/python3.8/contextlib.py:120: UserWarning: Creating scratch directories is taking a surprisingly long time. This is often due to running workers on a network file system. Consider specifying a local-directory to point workers to write scratch data to a local disk.
  next(self.gen)
distributed.worker - INFO -       Start worker at:  tcp://198.202.101.9:41911
distributed.worker - INFO -          Listening to:  tcp://198.202.101.9:41911
distributed.worker - INFO -          dashboard at:        198.202.101.9:46573
distributed.worker - INFO - Waiting to connect to: tcp://198.202.103.184:34547
distributed.worker - INFO - -------------------------------------------------
distributed.worker - INFO -               Threads:                          1
distributed.worker - INFO -                Memory:                    4.00 GB
distributed.worker - INFO -       Local Directory: /home/ntolley/Jones_Lab/sbi_hnn_github/code/ERP/dask-worker-space/dask-worker-space/worker-0uhra3zr
distributed.worker - INFO - -------------------------------------------------
/home/ntolley/anaconda3/envs/sbi/lib/python3.8/contextlib.py:120: UserWarning: Creating scratch directories is taking a surprisingly long time. This is often due to running workers on a network file system. Consider specifying a local-directory to point workers to write scratch data to a local disk.
  next(self.gen)
distributed.worker - INFO -       Start worker at:  tcp://198.202.101.9:33895
distributed.worker - INFO -          Listening to:  tcp://198.202.101.9:33895
distributed.worker - INFO -          dashboard at:        198.202.101.9:40069
distributed.worker - INFO - Waiting to connect to: tcp://198.202.103.184:34547
distributed.worker - INFO - -------------------------------------------------
distributed.worker - INFO -               Threads:                          1
distributed.worker - INFO -                Memory:                    4.00 GB
distributed.worker - INFO -       Local Directory: /home/ntolley/Jones_Lab/sbi_hnn_github/code/ERP/dask-worker-space/dask-worker-space/worker-uh38e5dc
distributed.worker - INFO - -------------------------------------------------
/home/ntolley/anaconda3/envs/sbi/lib/python3.8/contextlib.py:120: UserWarning: Creating scratch directories is taking a surprisingly long time. This is often due to running workers on a network file system. Consider specifying a local-directory to point workers to write scratch data to a local disk.
  next(self.gen)
distributed.worker - INFO -       Start worker at:  tcp://198.202.101.9:41323
distributed.worker - INFO -          Listening to:  tcp://198.202.101.9:41323
distributed.worker - INFO -          dashboard at:        198.202.101.9:46093
distributed.worker - INFO - Waiting to connect to: tcp://198.202.103.184:34547
distributed.worker - INFO - -------------------------------------------------
distributed.worker - INFO -               Threads:                          1
distributed.worker - INFO -                Memory:                    4.00 GB
distributed.worker - INFO -       Local Directory: /home/ntolley/Jones_Lab/sbi_hnn_github/code/ERP/dask-worker-space/dask-worker-space/worker-fqmnr3iv
distributed.worker - INFO - -------------------------------------------------
/home/ntolley/anaconda3/envs/sbi/lib/python3.8/contextlib.py:120: UserWarning: Creating scratch directories is taking a surprisingly long time. This is often due to running workers on a network file system. Consider specifying a local-directory to point workers to write scratch data to a local disk.
  next(self.gen)
distributed.worker - INFO -       Start worker at:  tcp://198.202.101.9:37881
distributed.worker - INFO -          Listening to:  tcp://198.202.101.9:37881
distributed.worker - INFO -          dashboard at:        198.202.101.9:42281
distributed.worker - INFO - Waiting to connect to: tcp://198.202.103.184:34547
distributed.worker - INFO - -------------------------------------------------
distributed.worker - INFO -               Threads:                          1
distributed.worker - INFO -                Memory:                    4.00 GB
distributed.worker - INFO -       Local Directory: /home/ntolley/Jones_Lab/sbi_hnn_github/code/ERP/dask-worker-space/dask-worker-space/worker-nz7i3bat
distributed.worker - INFO - -------------------------------------------------
/home/ntolley/anaconda3/envs/sbi/lib/python3.8/contextlib.py:120: UserWarning: Creating scratch directories is taking a surprisingly long time. This is often due to running workers on a network file system. Consider specifying a local-directory to point workers to write scratch data to a local disk.
  next(self.gen)
distributed.worker - INFO -       Start worker at:  tcp://198.202.101.9:38795
distributed.worker - INFO -          Listening to:  tcp://198.202.101.9:38795
distributed.worker - INFO -          dashboard at:        198.202.101.9:43023
distributed.worker - INFO - Waiting to connect to: tcp://198.202.103.184:34547
distributed.worker - INFO - -------------------------------------------------
distributed.worker - INFO -               Threads:                          1
distributed.worker - INFO -                Memory:                    4.00 GB
distributed.worker - INFO -       Local Directory: /home/ntolley/Jones_Lab/sbi_hnn_github/code/ERP/dask-worker-space/dask-worker-space/worker-jyc7ntyb
distributed.worker - INFO - -------------------------------------------------
/home/ntolley/anaconda3/envs/sbi/lib/python3.8/contextlib.py:120: UserWarning: Creating scratch directories is taking a surprisingly long time. This is often due to running workers on a network file system. Consider specifying a local-directory to point workers to write scratch data to a local disk.
  next(self.gen)
distributed.worker - INFO -       Start worker at:  tcp://198.202.101.9:37011
distributed.worker - INFO -          Listening to:  tcp://198.202.101.9:37011
distributed.worker - INFO -          dashboard at:        198.202.101.9:33397
distributed.worker - INFO - Waiting to connect to: tcp://198.202.103.184:34547
distributed.worker - INFO - -------------------------------------------------
distributed.worker - INFO -               Threads:                          1
distributed.worker - INFO -                Memory:                    4.00 GB
distributed.worker - INFO -       Local Directory: /home/ntolley/Jones_Lab/sbi_hnn_github/code/ERP/dask-worker-space/dask-worker-space/worker-2q6zz0nw
distributed.worker - INFO - -------------------------------------------------
/home/ntolley/anaconda3/envs/sbi/lib/python3.8/contextlib.py:120: UserWarning: Creating scratch directories is taking a surprisingly long time. This is often due to running workers on a network file system. Consider specifying a local-directory to point workers to write scratch data to a local disk.
  next(self.gen)
distributed.worker - INFO -       Start worker at:  tcp://198.202.101.9:39783
distributed.worker - INFO -          Listening to:  tcp://198.202.101.9:39783
distributed.worker - INFO -          dashboard at:        198.202.101.9:42789
distributed.worker - INFO - Waiting to connect to: tcp://198.202.103.184:34547
distributed.worker - INFO - -------------------------------------------------
distributed.worker - INFO -               Threads:                          1
distributed.worker - INFO -                Memory:                    4.00 GB
distributed.worker - INFO -       Local Directory: /home/ntolley/Jones_Lab/sbi_hnn_github/code/ERP/dask-worker-space/dask-worker-space/worker-o51xmige
distributed.worker - INFO - -------------------------------------------------
/home/ntolley/anaconda3/envs/sbi/lib/python3.8/contextlib.py:120: UserWarning: Creating scratch directories is taking a surprisingly long time. This is often due to running workers on a network file system. Consider specifying a local-directory to point workers to write scratch data to a local disk.
  next(self.gen)
distributed.worker - INFO -       Start worker at:  tcp://198.202.101.9:42035
distributed.worker - INFO -          Listening to:  tcp://198.202.101.9:42035
distributed.worker - INFO -          dashboard at:        198.202.101.9:43599
distributed.worker - INFO - Waiting to connect to: tcp://198.202.103.184:34547
distributed.worker - INFO - -------------------------------------------------
distributed.worker - INFO -               Threads:                          1
distributed.worker - INFO -                Memory:                    4.00 GB
distributed.worker - INFO -       Local Directory: /home/ntolley/Jones_Lab/sbi_hnn_github/code/ERP/dask-worker-space/dask-worker-space/worker-qwynjtvf
distributed.worker - INFO - -------------------------------------------------
/home/ntolley/anaconda3/envs/sbi/lib/python3.8/contextlib.py:120: UserWarning: Creating scratch directories is taking a surprisingly long time. This is often due to running workers on a network file system. Consider specifying a local-directory to point workers to write scratch data to a local disk.
  next(self.gen)
distributed.worker - INFO -       Start worker at:  tcp://198.202.101.9:44701
distributed.worker - INFO -          Listening to:  tcp://198.202.101.9:44701
distributed.worker - INFO -          dashboard at:        198.202.101.9:46611
distributed.worker - INFO - Waiting to connect to: tcp://198.202.103.184:34547
distributed.worker - INFO - -------------------------------------------------
distributed.worker - INFO -               Threads:                          1
distributed.worker - INFO -                Memory:                    4.00 GB
distributed.worker - INFO -       Local Directory: /home/ntolley/Jones_Lab/sbi_hnn_github/code/ERP/dask-worker-space/dask-worker-space/worker-89aoacm3
distributed.worker - INFO - -------------------------------------------------
/home/ntolley/anaconda3/envs/sbi/lib/python3.8/contextlib.py:120: UserWarning: Creating scratch directories is taking a surprisingly long time. This is often due to running workers on a network file system. Consider specifying a local-directory to point workers to write scratch data to a local disk.
  next(self.gen)
distributed.worker - INFO -       Start worker at:  tcp://198.202.101.9:41997
distributed.worker - INFO -          Listening to:  tcp://198.202.101.9:41997
distributed.worker - INFO -          dashboard at:        198.202.101.9:42047
distributed.worker - INFO - Waiting to connect to: tcp://198.202.103.184:34547
distributed.worker - INFO - -------------------------------------------------
distributed.worker - INFO -               Threads:                          1
distributed.worker - INFO -                Memory:                    4.00 GB
distributed.worker - INFO -       Local Directory: /home/ntolley/Jones_Lab/sbi_hnn_github/code/ERP/dask-worker-space/dask-worker-space/worker-b7ngt_4z
distributed.worker - INFO - -------------------------------------------------
/home/ntolley/anaconda3/envs/sbi/lib/python3.8/contextlib.py:120: UserWarning: Creating scratch directories is taking a surprisingly long time. This is often due to running workers on a network file system. Consider specifying a local-directory to point workers to write scratch data to a local disk.
  next(self.gen)
distributed.worker - INFO -       Start worker at:  tcp://198.202.101.9:39157
distributed.worker - INFO -          Listening to:  tcp://198.202.101.9:39157
distributed.worker - INFO -          dashboard at:        198.202.101.9:36333
distributed.worker - INFO - Waiting to connect to: tcp://198.202.103.184:34547
distributed.worker - INFO - -------------------------------------------------
distributed.worker - INFO -               Threads:                          1
distributed.worker - INFO -                Memory:                    4.00 GB
distributed.worker - INFO -       Local Directory: /home/ntolley/Jones_Lab/sbi_hnn_github/code/ERP/dask-worker-space/dask-worker-space/worker-zc9bmpdz
distributed.worker - INFO - -------------------------------------------------
/home/ntolley/anaconda3/envs/sbi/lib/python3.8/contextlib.py:120: UserWarning: Creating scratch directories is taking a surprisingly long time. This is often due to running workers on a network file system. Consider specifying a local-directory to point workers to write scratch data to a local disk.
  next(self.gen)
distributed.worker - INFO -       Start worker at:  tcp://198.202.101.9:42399
distributed.worker - INFO -          Listening to:  tcp://198.202.101.9:42399
distributed.worker - INFO -          dashboard at:        198.202.101.9:43571
distributed.worker - INFO - Waiting to connect to: tcp://198.202.103.184:34547
distributed.worker - INFO - -------------------------------------------------
distributed.worker - INFO -               Threads:                          1
distributed.worker - INFO -                Memory:                    4.00 GB
distributed.worker - INFO -       Local Directory: /home/ntolley/Jones_Lab/sbi_hnn_github/code/ERP/dask-worker-space/dask-worker-space/worker-1w49yf7l
distributed.worker - INFO - -------------------------------------------------
/home/ntolley/anaconda3/envs/sbi/lib/python3.8/contextlib.py:120: UserWarning: Creating scratch directories is taking a surprisingly long time. This is often due to running workers on a network file system. Consider specifying a local-directory to point workers to write scratch data to a local disk.
  next(self.gen)
distributed.worker - INFO -       Start worker at:  tcp://198.202.101.9:38503
distributed.worker - INFO -          Listening to:  tcp://198.202.101.9:38503
distributed.worker - INFO -          dashboard at:        198.202.101.9:38417
distributed.worker - INFO - Waiting to connect to: tcp://198.202.103.184:34547
distributed.worker - INFO - -------------------------------------------------
distributed.worker - INFO -               Threads:                          1
distributed.worker - INFO -                Memory:                    4.00 GB
distributed.worker - INFO -       Local Directory: /home/ntolley/Jones_Lab/sbi_hnn_github/code/ERP/dask-worker-space/dask-worker-space/worker-mvpb_rqm
distributed.worker - INFO - -------------------------------------------------
/home/ntolley/anaconda3/envs/sbi/lib/python3.8/contextlib.py:120: UserWarning: Creating scratch directories is taking a surprisingly long time. This is often due to running workers on a network file system. Consider specifying a local-directory to point workers to write scratch data to a local disk.
  next(self.gen)
distributed.worker - INFO -       Start worker at:  tcp://198.202.101.9:40853
distributed.worker - INFO -          Listening to:  tcp://198.202.101.9:40853
distributed.worker - INFO -          dashboard at:        198.202.101.9:44559
distributed.worker - INFO - Waiting to connect to: tcp://198.202.103.184:34547
distributed.worker - INFO - -------------------------------------------------
distributed.worker - INFO -               Threads:                          1
distributed.worker - INFO -                Memory:                    4.00 GB
distributed.worker - INFO -       Local Directory: /home/ntolley/Jones_Lab/sbi_hnn_github/code/ERP/dask-worker-space/dask-worker-space/worker-wbjo4sou
distributed.worker - INFO - -------------------------------------------------
/home/ntolley/anaconda3/envs/sbi/lib/python3.8/contextlib.py:120: UserWarning: Creating scratch directories is taking a surprisingly long time. This is often due to running workers on a network file system. Consider specifying a local-directory to point workers to write scratch data to a local disk.
  next(self.gen)
distributed.worker - INFO -       Start worker at:  tcp://198.202.101.9:35215
distributed.worker - INFO -          Listening to:  tcp://198.202.101.9:35215
distributed.worker - INFO -          dashboard at:        198.202.101.9:35971
distributed.worker - INFO - Waiting to connect to: tcp://198.202.103.184:34547
distributed.worker - INFO - -------------------------------------------------
distributed.worker - INFO -               Threads:                          1
distributed.worker - INFO -                Memory:                    4.00 GB
distributed.worker - INFO -       Local Directory: /home/ntolley/Jones_Lab/sbi_hnn_github/code/ERP/dask-worker-space/dask-worker-space/worker-o7y05isy
distributed.worker - INFO - -------------------------------------------------
/home/ntolley/anaconda3/envs/sbi/lib/python3.8/contextlib.py:120: UserWarning: Creating scratch directories is taking a surprisingly long time. This is often due to running workers on a network file system. Consider specifying a local-directory to point workers to write scratch data to a local disk.
  next(self.gen)
distributed.worker - INFO -       Start worker at:  tcp://198.202.101.9:39737
distributed.worker - INFO -          Listening to:  tcp://198.202.101.9:39737
distributed.worker - INFO -          dashboard at:        198.202.101.9:42551
distributed.worker - INFO - Waiting to connect to: tcp://198.202.103.184:34547
distributed.worker - INFO - -------------------------------------------------
distributed.worker - INFO -               Threads:                          1
distributed.worker - INFO -                Memory:                    4.00 GB
distributed.worker - INFO -       Local Directory: /home/ntolley/Jones_Lab/sbi_hnn_github/code/ERP/dask-worker-space/dask-worker-space/worker-6h4av_wu
distributed.worker - INFO - -------------------------------------------------
/home/ntolley/anaconda3/envs/sbi/lib/python3.8/contextlib.py:120: UserWarning: Creating scratch directories is taking a surprisingly long time. This is often due to running workers on a network file system. Consider specifying a local-directory to point workers to write scratch data to a local disk.
  next(self.gen)
distributed.worker - INFO -       Start worker at:  tcp://198.202.101.9:39911
distributed.worker - INFO -          Listening to:  tcp://198.202.101.9:39911
distributed.worker - INFO -          dashboard at:        198.202.101.9:36869
distributed.worker - INFO - Waiting to connect to: tcp://198.202.103.184:34547
distributed.worker - INFO - -------------------------------------------------
distributed.worker - INFO -               Threads:                          1
/home/ntolley/anaconda3/envs/sbi/lib/python3.8/contextlib.py:120: UserWarning: Creating scratch directories is taking a surprisingly long time. This is often due to running workers on a network file system. Consider specifying a local-directory to point workers to write scratch data to a local disk.
  next(self.gen)
distributed.worker - INFO -       Start worker at:  tcp://198.202.101.9:39261
distributed.worker - INFO -                Memory:                    4.00 GB
distributed.worker - INFO -          Listening to:  tcp://198.202.101.9:39261
distributed.worker - INFO -       Local Directory: /home/ntolley/Jones_Lab/sbi_hnn_github/code/ERP/dask-worker-space/dask-worker-space/worker-dlzseg97
distributed.worker - INFO -          dashboard at:        198.202.101.9:46307
distributed.worker - INFO - Waiting to connect to: tcp://198.202.103.184:34547
distributed.worker - INFO - -------------------------------------------------
distributed.worker - INFO - -------------------------------------------------
distributed.worker - INFO -               Threads:                          1
distributed.worker - INFO -                Memory:                    4.00 GB
distributed.worker - INFO -       Local Directory: /home/ntolley/Jones_Lab/sbi_hnn_github/code/ERP/dask-worker-space/dask-worker-space/worker-55e94l8h
distributed.worker - INFO - -------------------------------------------------
/home/ntolley/anaconda3/envs/sbi/lib/python3.8/contextlib.py:120: UserWarning: Creating scratch directories is taking a surprisingly long time. This is often due to running workers on a network file system. Consider specifying a local-directory to point workers to write scratch data to a local disk.
  next(self.gen)
distributed.worker - INFO -       Start worker at:  tcp://198.202.101.9:44989
distributed.worker - INFO -          Listening to:  tcp://198.202.101.9:44989
distributed.worker - INFO -          dashboard at:        198.202.101.9:45581
distributed.worker - INFO - Waiting to connect to: tcp://198.202.103.184:34547
distributed.worker - INFO - -------------------------------------------------
distributed.worker - INFO -               Threads:                          1
distributed.worker - INFO -                Memory:                    4.00 GB
distributed.worker - INFO -       Local Directory: /home/ntolley/Jones_Lab/sbi_hnn_github/code/ERP/dask-worker-space/dask-worker-space/worker-ltqmo8b6
distributed.worker - INFO - -------------------------------------------------
/home/ntolley/anaconda3/envs/sbi/lib/python3.8/contextlib.py:120: UserWarning: Creating scratch directories is taking a surprisingly long time. This is often due to running workers on a network file system. Consider specifying a local-directory to point workers to write scratch data to a local disk.
  next(self.gen)
distributed.worker - INFO -       Start worker at:  tcp://198.202.101.9:41883
distributed.worker - INFO -          Listening to:  tcp://198.202.101.9:41883
distributed.worker - INFO -          dashboard at:        198.202.101.9:37545
distributed.worker - INFO - Waiting to connect to: tcp://198.202.103.184:34547
distributed.worker - INFO - -------------------------------------------------
distributed.worker - INFO -               Threads:                          1
distributed.worker - INFO -                Memory:                    4.00 GB
distributed.worker - INFO -       Local Directory: /home/ntolley/Jones_Lab/sbi_hnn_github/code/ERP/dask-worker-space/dask-worker-space/worker-nh1q4t4t
distributed.worker - INFO - -------------------------------------------------
/home/ntolley/anaconda3/envs/sbi/lib/python3.8/contextlib.py:120: UserWarning: Creating scratch directories is taking a surprisingly long time. This is often due to running workers on a network file system. Consider specifying a local-directory to point workers to write scratch data to a local disk.
  next(self.gen)
distributed.worker - INFO -       Start worker at:  tcp://198.202.101.9:44099
distributed.worker - INFO -          Listening to:  tcp://198.202.101.9:44099
distributed.worker - INFO -          dashboard at:        198.202.101.9:36427
distributed.worker - INFO - Waiting to connect to: tcp://198.202.103.184:34547
distributed.worker - INFO - -------------------------------------------------
distributed.worker - INFO -               Threads:                          1
distributed.worker - INFO -                Memory:                    4.00 GB
distributed.worker - INFO -       Local Directory: /home/ntolley/Jones_Lab/sbi_hnn_github/code/ERP/dask-worker-space/dask-worker-space/worker-7d4wpvra
distributed.worker - INFO - -------------------------------------------------
/home/ntolley/anaconda3/envs/sbi/lib/python3.8/contextlib.py:120: UserWarning: Creating scratch directories is taking a surprisingly long time. This is often due to running workers on a network file system. Consider specifying a local-directory to point workers to write scratch data to a local disk.
  next(self.gen)
distributed.worker - INFO -       Start worker at:  tcp://198.202.101.9:38207
distributed.worker - INFO -          Listening to:  tcp://198.202.101.9:38207
/home/ntolley/anaconda3/envs/sbi/lib/python3.8/contextlib.py:120: UserWarning: Creating scratch directories is taking a surprisingly long time. This is often due to running workers on a network file system. Consider specifying a local-directory to point workers to write scratch data to a local disk.
  next(self.gen)
distributed.worker - INFO -       Start worker at:  tcp://198.202.101.9:45049
distributed.worker - INFO -          dashboard at:        198.202.101.9:33825
distributed.worker - INFO - Waiting to connect to: tcp://198.202.103.184:34547
distributed.worker - INFO - -------------------------------------------------
distributed.worker - INFO -               Threads:                          1
distributed.worker - INFO -          Listening to:  tcp://198.202.101.9:45049
distributed.worker - INFO -                Memory:                    4.00 GB
distributed.worker - INFO -       Local Directory: /home/ntolley/Jones_Lab/sbi_hnn_github/code/ERP/dask-worker-space/dask-worker-space/worker-eaxyrska
distributed.worker - INFO -          dashboard at:        198.202.101.9:39281
distributed.worker - INFO - Waiting to connect to: tcp://198.202.103.184:34547
distributed.worker - INFO - -------------------------------------------------
distributed.worker - INFO - -------------------------------------------------
distributed.worker - INFO -               Threads:                          1
distributed.worker - INFO -                Memory:                    4.00 GB
distributed.worker - INFO -       Local Directory: /home/ntolley/Jones_Lab/sbi_hnn_github/code/ERP/dask-worker-space/dask-worker-space/worker-jhy9qmnv
distributed.worker - INFO - -------------------------------------------------
/home/ntolley/anaconda3/envs/sbi/lib/python3.8/contextlib.py:120: UserWarning: Creating scratch directories is taking a surprisingly long time. This is often due to running workers on a network file system. Consider specifying a local-directory to point workers to write scratch data to a local disk.
  next(self.gen)
distributed.worker - INFO -       Start worker at:  tcp://198.202.101.9:38621
distributed.worker - INFO -          Listening to:  tcp://198.202.101.9:38621
distributed.worker - INFO -          dashboard at:        198.202.101.9:45099
distributed.worker - INFO - Waiting to connect to: tcp://198.202.103.184:34547
distributed.worker - INFO - -------------------------------------------------
distributed.worker - INFO -               Threads:                          1
distributed.worker - INFO -                Memory:                    4.00 GB
distributed.worker - INFO -       Local Directory: /home/ntolley/Jones_Lab/sbi_hnn_github/code/ERP/dask-worker-space/dask-worker-space/worker-fs2zivi3
distributed.worker - INFO - -------------------------------------------------
/home/ntolley/anaconda3/envs/sbi/lib/python3.8/contextlib.py:120: UserWarning: Creating scratch directories is taking a surprisingly long time. This is often due to running workers on a network file system. Consider specifying a local-directory to point workers to write scratch data to a local disk.
  next(self.gen)
distributed.worker - INFO -       Start worker at:  tcp://198.202.101.9:35881
distributed.worker - INFO -          Listening to:  tcp://198.202.101.9:35881
distributed.worker - INFO -          dashboard at:        198.202.101.9:36131
distributed.worker - INFO - Waiting to connect to: tcp://198.202.103.184:34547
distributed.worker - INFO - -------------------------------------------------
distributed.worker - INFO -               Threads:                          1
distributed.worker - INFO -                Memory:                    4.00 GB
distributed.worker - INFO -       Local Directory: /home/ntolley/Jones_Lab/sbi_hnn_github/code/ERP/dask-worker-space/dask-worker-space/worker-rr_xbk0o
distributed.worker - INFO - -------------------------------------------------
/home/ntolley/anaconda3/envs/sbi/lib/python3.8/contextlib.py:120: UserWarning: Creating scratch directories is taking a surprisingly long time. This is often due to running workers on a network file system. Consider specifying a local-directory to point workers to write scratch data to a local disk.
  next(self.gen)
distributed.worker - INFO -       Start worker at:  tcp://198.202.101.9:41783
distributed.worker - INFO -          Listening to:  tcp://198.202.101.9:41783
distributed.worker - INFO -          dashboard at:        198.202.101.9:36001
distributed.worker - INFO - Waiting to connect to: tcp://198.202.103.184:34547
distributed.worker - INFO - -------------------------------------------------
distributed.worker - INFO -               Threads:                          1
distributed.worker - INFO -                Memory:                    4.00 GB
distributed.worker - INFO -       Local Directory: /home/ntolley/Jones_Lab/sbi_hnn_github/code/ERP/dask-worker-space/dask-worker-space/worker-x9w64otp
distributed.worker - INFO - -------------------------------------------------
/home/ntolley/anaconda3/envs/sbi/lib/python3.8/contextlib.py:120: UserWarning: Creating scratch directories is taking a surprisingly long time. This is often due to running workers on a network file system. Consider specifying a local-directory to point workers to write scratch data to a local disk.
  next(self.gen)
distributed.worker - INFO -       Start worker at:  tcp://198.202.101.9:41933
distributed.worker - INFO -          Listening to:  tcp://198.202.101.9:41933
distributed.worker - INFO -          dashboard at:        198.202.101.9:43183
distributed.worker - INFO - Waiting to connect to: tcp://198.202.103.184:34547
distributed.worker - INFO - -------------------------------------------------
distributed.worker - INFO -               Threads:                          1
distributed.worker - INFO -                Memory:                    4.00 GB
distributed.worker - INFO -       Local Directory: /home/ntolley/Jones_Lab/sbi_hnn_github/code/ERP/dask-worker-space/dask-worker-space/worker-ze0160zh
distributed.worker - INFO - -------------------------------------------------
/home/ntolley/anaconda3/envs/sbi/lib/python3.8/contextlib.py:120: UserWarning: Creating scratch directories is taking a surprisingly long time. This is often due to running workers on a network file system. Consider specifying a local-directory to point workers to write scratch data to a local disk.
  next(self.gen)
distributed.worker - INFO -       Start worker at:  tcp://198.202.101.9:36123
distributed.worker - INFO -          Listening to:  tcp://198.202.101.9:36123
distributed.worker - INFO -          dashboard at:        198.202.101.9:39901
distributed.worker - INFO - Waiting to connect to: tcp://198.202.103.184:34547
distributed.worker - INFO - -------------------------------------------------
distributed.worker - INFO -               Threads:                          1
distributed.worker - INFO -                Memory:                    4.00 GB
distributed.worker - INFO -       Local Directory: /home/ntolley/Jones_Lab/sbi_hnn_github/code/ERP/dask-worker-space/dask-worker-space/worker-6a_i334q
distributed.worker - INFO - -------------------------------------------------
/home/ntolley/anaconda3/envs/sbi/lib/python3.8/contextlib.py:120: UserWarning: Creating scratch directories is taking a surprisingly long time. This is often due to running workers on a network file system. Consider specifying a local-directory to point workers to write scratch data to a local disk.
  next(self.gen)
distributed.worker - INFO -       Start worker at:  tcp://198.202.101.9:39727
distributed.worker - INFO -          Listening to:  tcp://198.202.101.9:39727
distributed.worker - INFO -          dashboard at:        198.202.101.9:44509
distributed.worker - INFO - Waiting to connect to: tcp://198.202.103.184:34547
distributed.worker - INFO - -------------------------------------------------
distributed.worker - INFO -               Threads:                          1
distributed.worker - INFO -                Memory:                    4.00 GB
distributed.worker - INFO -       Local Directory: /home/ntolley/Jones_Lab/sbi_hnn_github/code/ERP/dask-worker-space/dask-worker-space/worker-zkuz5ebd
distributed.worker - INFO - -------------------------------------------------
/home/ntolley/anaconda3/envs/sbi/lib/python3.8/contextlib.py:120: UserWarning: Creating scratch directories is taking a surprisingly long time. This is often due to running workers on a network file system. Consider specifying a local-directory to point workers to write scratch data to a local disk.
  next(self.gen)
distributed.worker - INFO -       Start worker at:  tcp://198.202.101.9:44621
distributed.worker - INFO -          Listening to:  tcp://198.202.101.9:44621
distributed.worker - INFO -          dashboard at:        198.202.101.9:39173
distributed.worker - INFO - Waiting to connect to: tcp://198.202.103.184:34547
distributed.worker - INFO - -------------------------------------------------
distributed.worker - INFO -               Threads:                          1
distributed.worker - INFO -                Memory:                    4.00 GB
/home/ntolley/anaconda3/envs/sbi/lib/python3.8/contextlib.py:120: UserWarning: Creating scratch directories is taking a surprisingly long time. This is often due to running workers on a network file system. Consider specifying a local-directory to point workers to write scratch data to a local disk.
  next(self.gen)
distributed.worker - INFO -       Start worker at:  tcp://198.202.101.9:41005
distributed.worker - INFO -       Local Directory: /home/ntolley/Jones_Lab/sbi_hnn_github/code/ERP/dask-worker-space/dask-worker-space/worker-4z1qwo02
distributed.worker - INFO - -------------------------------------------------
distributed.worker - INFO -          Listening to:  tcp://198.202.101.9:41005
distributed.worker - INFO -          dashboard at:        198.202.101.9:40677
distributed.worker - INFO - Waiting to connect to: tcp://198.202.103.184:34547
distributed.worker - INFO - -------------------------------------------------
distributed.worker - INFO -               Threads:                          1
distributed.worker - INFO -                Memory:                    4.00 GB
distributed.worker - INFO -       Local Directory: /home/ntolley/Jones_Lab/sbi_hnn_github/code/ERP/dask-worker-space/dask-worker-space/worker-kivar09i
distributed.worker - INFO - -------------------------------------------------
distributed.worker - INFO -         Registered to: tcp://198.202.103.184:34547
distributed.worker - INFO - -------------------------------------------------
distributed.core - INFO - Starting established connection
distributed.worker - INFO -         Registered to: tcp://198.202.103.184:34547
distributed.worker - INFO - -------------------------------------------------
distributed.core - INFO - Starting established connection
distributed.worker - INFO -         Registered to: tcp://198.202.103.184:34547
distributed.worker - INFO - -------------------------------------------------
distributed.core - INFO - Starting established connection
distributed.worker - INFO -         Registered to: tcp://198.202.103.184:34547
distributed.worker - INFO - -------------------------------------------------
distributed.core - INFO - Starting established connection
distributed.worker - INFO -         Registered to: tcp://198.202.103.184:34547
distributed.worker - INFO - -------------------------------------------------
distributed.core - INFO - Starting established connection
distributed.worker - INFO -         Registered to: tcp://198.202.103.184:34547
distributed.worker - INFO - -------------------------------------------------
distributed.core - INFO - Starting established connection
distributed.worker - INFO -         Registered to: tcp://198.202.103.184:34547
distributed.worker - INFO - -------------------------------------------------
distributed.core - INFO - Starting established connection
distributed.worker - INFO -         Registered to: tcp://198.202.103.184:34547
distributed.worker - INFO - -------------------------------------------------
distributed.core - INFO - Starting established connection
distributed.worker - INFO -         Registered to: tcp://198.202.103.184:34547
distributed.worker - INFO - -------------------------------------------------
distributed.core - INFO - Starting established connection
distributed.worker - INFO -         Registered to: tcp://198.202.103.184:34547
distributed.worker - INFO - -------------------------------------------------
distributed.core - INFO - Starting established connection
distributed.worker - INFO -         Registered to: tcp://198.202.103.184:34547
distributed.worker - INFO - -------------------------------------------------
distributed.core - INFO - Starting established connection
distributed.worker - INFO -         Registered to: tcp://198.202.103.184:34547
distributed.worker - INFO - -------------------------------------------------
distributed.core - INFO - Starting established connection
distributed.worker - INFO -         Registered to: tcp://198.202.103.184:34547
distributed.worker - INFO - -------------------------------------------------
distributed.core - INFO - Starting established connection
distributed.worker - INFO -         Registered to: tcp://198.202.103.184:34547
distributed.worker - INFO - -------------------------------------------------
distributed.core - INFO - Starting established connection
distributed.worker - INFO -         Registered to: tcp://198.202.103.184:34547
distributed.worker - INFO - -------------------------------------------------
distributed.core - INFO - Starting established connection
distributed.worker - INFO -         Registered to: tcp://198.202.103.184:34547
distributed.worker - INFO - -------------------------------------------------
distributed.core - INFO - Starting established connection
distributed.worker - INFO -         Registered to: tcp://198.202.103.184:34547
distributed.worker - INFO - -------------------------------------------------
distributed.core - INFO - Starting established connection
distributed.worker - INFO -         Registered to: tcp://198.202.103.184:34547
distributed.worker - INFO - -------------------------------------------------
distributed.core - INFO - Starting established connection
distributed.worker - INFO -         Registered to: tcp://198.202.103.184:34547
distributed.worker - INFO - -------------------------------------------------
distributed.core - INFO - Starting established connection
distributed.worker - INFO -         Registered to: tcp://198.202.103.184:34547
distributed.worker - INFO - -------------------------------------------------
distributed.core - INFO - Starting established connection
distributed.worker - INFO -         Registered to: tcp://198.202.103.184:34547
distributed.worker - INFO - -------------------------------------------------
distributed.core - INFO - Starting established connection
distributed.worker - INFO -         Registered to: tcp://198.202.103.184:34547
distributed.worker - INFO - -------------------------------------------------
distributed.core - INFO - Starting established connection
distributed.worker - INFO -         Registered to: tcp://198.202.103.184:34547
distributed.worker - INFO - -------------------------------------------------
distributed.core - INFO - Starting established connection
distributed.worker - INFO -         Registered to: tcp://198.202.103.184:34547
distributed.worker - INFO - -------------------------------------------------
distributed.core - INFO - Starting established connection
distributed.worker - INFO -         Registered to: tcp://198.202.103.184:34547
distributed.worker - INFO - -------------------------------------------------
distributed.core - INFO - Starting established connection
distributed.worker - INFO -         Registered to: tcp://198.202.103.184:34547
distributed.worker - INFO - -------------------------------------------------
distributed.core - INFO - Starting established connection
distributed.worker - INFO -         Registered to: tcp://198.202.103.184:34547
distributed.worker - INFO - -------------------------------------------------
distributed.core - INFO - Starting established connection
distributed.worker - INFO -         Registered to: tcp://198.202.103.184:34547
distributed.worker - INFO - -------------------------------------------------
distributed.core - INFO - Starting established connection
distributed.worker - INFO -         Registered to: tcp://198.202.103.184:34547
distributed.worker - INFO - -------------------------------------------------
distributed.core - INFO - Starting established connection
distributed.worker - INFO -         Registered to: tcp://198.202.103.184:34547
distributed.worker - INFO - -------------------------------------------------
distributed.core - INFO - Starting established connection
distributed.worker - INFO -         Registered to: tcp://198.202.103.184:34547
distributed.worker - INFO - -------------------------------------------------
distributed.core - INFO - Starting established connection
distributed.worker - INFO -         Registered to: tcp://198.202.103.184:34547
distributed.worker - INFO - -------------------------------------------------
distributed.core - INFO - Starting established connection
distributed.worker - INFO -         Registered to: tcp://198.202.103.184:34547
distributed.worker - INFO - -------------------------------------------------
distributed.core - INFO - Starting established connection
distributed.worker - INFO -         Registered to: tcp://198.202.103.184:34547
distributed.worker - INFO - -------------------------------------------------
distributed.core - INFO - Starting established connection
distributed.worker - INFO -         Registered to: tcp://198.202.103.184:34547
distributed.worker - INFO - -------------------------------------------------
distributed.core - INFO - Starting established connection
distributed.worker - INFO -         Registered to: tcp://198.202.103.184:34547
distributed.worker - INFO - -------------------------------------------------
distributed.core - INFO - Starting established connection
distributed.worker - INFO -         Registered to: tcp://198.202.103.184:34547
distributed.worker - INFO - -------------------------------------------------
distributed.core - INFO - Starting established connection
distributed.worker - INFO -         Registered to: tcp://198.202.103.184:34547
distributed.worker - INFO - -------------------------------------------------
distributed.core - INFO - Starting established connection
distributed.worker - INFO -         Registered to: tcp://198.202.103.184:34547
distributed.worker - INFO - -------------------------------------------------
distributed.core - INFO - Starting established connection
distributed.worker - INFO -         Registered to: tcp://198.202.103.184:34547
distributed.worker - INFO - -------------------------------------------------
distributed.core - INFO - Starting established connection
distributed.worker - INFO -         Registered to: tcp://198.202.103.184:34547
distributed.worker - INFO - -------------------------------------------------
distributed.core - INFO - Starting established connection
distributed.worker - INFO -         Registered to: tcp://198.202.103.184:34547
distributed.worker - INFO - -------------------------------------------------
distributed.core - INFO - Starting established connection
distributed.worker - INFO -         Registered to: tcp://198.202.103.184:34547
distributed.worker - INFO - -------------------------------------------------
distributed.core - INFO - Starting established connection
distributed.worker - INFO -         Registered to: tcp://198.202.103.184:34547
distributed.worker - INFO - -------------------------------------------------
distributed.core - INFO - Starting established connection
distributed.worker - INFO -         Registered to: tcp://198.202.103.184:34547
distributed.worker - INFO - -------------------------------------------------
distributed.core - INFO - Starting established connection
distributed.worker - INFO -         Registered to: tcp://198.202.103.184:34547
distributed.worker - INFO - -------------------------------------------------
distributed.core - INFO - Starting established connection
distributed.worker - INFO -         Registered to: tcp://198.202.103.184:34547
distributed.worker - INFO - -------------------------------------------------
distributed.core - INFO - Starting established connection
distributed.worker - INFO -         Registered to: tcp://198.202.103.184:34547
distributed.worker - INFO - -------------------------------------------------
distributed.core - INFO - Starting established connection
distributed.worker - INFO -         Registered to: tcp://198.202.103.184:34547
distributed.worker - INFO - -------------------------------------------------
distributed.core - INFO - Starting established connection
distributed.worker - INFO -         Registered to: tcp://198.202.103.184:34547
distributed.worker - INFO - -------------------------------------------------
distributed.core - INFO - Starting established connection
distributed.worker - WARNING - Heartbeat to scheduler failed
distributed.worker - WARNING - Heartbeat to scheduler failed
distributed.worker - WARNING - Heartbeat to scheduler failed
distributed.worker - WARNING - Heartbeat to scheduler failed
distributed.worker - WARNING - Heartbeat to scheduler failed
distributed.worker - WARNING - Heartbeat to scheduler failed
distributed.worker - WARNING - Heartbeat to scheduler failed
distributed.worker - WARNING - Heartbeat to scheduler failed
distributed.worker - WARNING - Heartbeat to scheduler failed
distributed.worker - WARNING - Heartbeat to scheduler failed
distributed.worker - WARNING - Heartbeat to scheduler failed
distributed.worker - WARNING - Heartbeat to scheduler failed
distributed.worker - WARNING - Heartbeat to scheduler failed
distributed.worker - WARNING - Heartbeat to scheduler failed
distributed.worker - WARNING - Heartbeat to scheduler failed
distributed.worker - WARNING - Heartbeat to scheduler failed
distributed.worker - WARNING - Heartbeat to scheduler failed
distributed.worker - WARNING - Heartbeat to scheduler failed
distributed.worker - WARNING - Heartbeat to scheduler failed
distributed.worker - WARNING - Heartbeat to scheduler failed
distributed.worker - WARNING - Heartbeat to scheduler failed
distributed.worker - WARNING - Heartbeat to scheduler failed
distributed.worker - WARNING - Heartbeat to scheduler failed
distributed.worker - WARNING - Heartbeat to scheduler failed
distributed.worker - WARNING - Heartbeat to scheduler failed
distributed.worker - WARNING - Heartbeat to scheduler failed
distributed.worker - WARNING - Heartbeat to scheduler failed
distributed.worker - WARNING - Heartbeat to scheduler failed
distributed.worker - WARNING - Heartbeat to scheduler failed
distributed.worker - WARNING - Heartbeat to scheduler failed
distributed.worker - WARNING - Heartbeat to scheduler failed
distributed.worker - WARNING - Heartbeat to scheduler failed
distributed.worker - WARNING - Heartbeat to scheduler failed
distributed.worker - WARNING - Heartbeat to scheduler failed
distributed.worker - WARNING - Heartbeat to scheduler failed
distributed.worker - WARNING - Heartbeat to scheduler failed
distributed.worker - WARNING - Heartbeat to scheduler failed
distributed.worker - WARNING - Heartbeat to scheduler failed
distributed.worker - WARNING - Heartbeat to scheduler failed
distributed.worker - WARNING - Heartbeat to scheduler failed
distributed.worker - WARNING - Heartbeat to scheduler failed
distributed.worker - WARNING - Heartbeat to scheduler failed
distributed.worker - WARNING - Heartbeat to scheduler failed
distributed.worker - WARNING - Heartbeat to scheduler failed
distributed.worker - WARNING - Heartbeat to scheduler failed
distributed.worker - WARNING - Heartbeat to scheduler failed
distributed.worker - WARNING - Heartbeat to scheduler failed
distributed.worker - WARNING - Heartbeat to scheduler failed
distributed.worker - WARNING - Heartbeat to scheduler failed
distributed.worker - WARNING - Heartbeat to scheduler failed
distributed.worker - INFO - Connection to scheduler broken.  Reconnecting...
distributed.worker - INFO - Connection to scheduler broken.  Reconnecting...
distributed.worker - INFO - Connection to scheduler broken.  Reconnecting...
distributed.worker - INFO - Connection to scheduler broken.  Reconnecting...
distributed.worker - INFO - Connection to scheduler broken.  Reconnecting...
distributed.worker - INFO - Connection to scheduler broken.  Reconnecting...
distributed.worker - INFO - Connection to scheduler broken.  Reconnecting...
distributed.worker - INFO - Connection to scheduler broken.  Reconnecting...
distributed.worker - INFO - Connection to scheduler broken.  Reconnecting...
distributed.worker - INFO - Connection to scheduler broken.  Reconnecting...
distributed.worker - INFO - Connection to scheduler broken.  Reconnecting...
distributed.worker - INFO - Connection to scheduler broken.  Reconnecting...
distributed.worker - INFO - Connection to scheduler broken.  Reconnecting...
distributed.worker - INFO - Connection to scheduler broken.  Reconnecting...
distributed.worker - INFO - Connection to scheduler broken.  Reconnecting...
distributed.worker - INFO - Connection to scheduler broken.  Reconnecting...
distributed.worker - INFO - Connection to scheduler broken.  Reconnecting...
distributed.worker - INFO - Connection to scheduler broken.  Reconnecting...
distributed.worker - INFO - Connection to scheduler broken.  Reconnecting...
distributed.worker - INFO - Connection to scheduler broken.  Reconnecting...
distributed.worker - INFO - Connection to scheduler broken.  Reconnecting...
distributed.worker - INFO - Connection to scheduler broken.  Reconnecting...
distributed.worker - INFO - Connection to scheduler broken.  Reconnecting...
distributed.worker - INFO - Connection to scheduler broken.  Reconnecting...
distributed.worker - INFO - Connection to scheduler broken.  Reconnecting...
distributed.worker - INFO - Connection to scheduler broken.  Reconnecting...
distributed.worker - INFO - Connection to scheduler broken.  Reconnecting...
distributed.worker - INFO - Connection to scheduler broken.  Reconnecting...
distributed.worker - INFO - Connection to scheduler broken.  Reconnecting...
distributed.worker - INFO - Connection to scheduler broken.  Reconnecting...
distributed.worker - INFO - Connection to scheduler broken.  Reconnecting...
distributed.worker - INFO - Connection to scheduler broken.  Reconnecting...
distributed.worker - INFO - Connection to scheduler broken.  Reconnecting...
distributed.worker - INFO - Connection to scheduler broken.  Reconnecting...
distributed.worker - INFO - Connection to scheduler broken.  Reconnecting...
distributed.worker - INFO - Connection to scheduler broken.  Reconnecting...
distributed.worker - INFO - Connection to scheduler broken.  Reconnecting...
distributed.worker - INFO - Connection to scheduler broken.  Reconnecting...
distributed.worker - INFO - Connection to scheduler broken.  Reconnecting...
distributed.worker - INFO - Connection to scheduler broken.  Reconnecting...
distributed.worker - INFO - Connection to scheduler broken.  Reconnecting...
distributed.worker - INFO - Connection to scheduler broken.  Reconnecting...
distributed.worker - INFO - Connection to scheduler broken.  Reconnecting...
distributed.worker - INFO - Connection to scheduler broken.  Reconnecting...
distributed.worker - INFO - Connection to scheduler broken.  Reconnecting...
distributed.worker - INFO - Connection to scheduler broken.  Reconnecting...
distributed.worker - INFO - Connection to scheduler broken.  Reconnecting...
distributed.worker - INFO - Connection to scheduler broken.  Reconnecting...
distributed.worker - INFO - Connection to scheduler broken.  Reconnecting...
distributed.worker - INFO - Connection to scheduler broken.  Reconnecting...
tornado.application - ERROR - Exception in callback functools.partial(<bound method IOLoop._discard_future_result of <tornado.platform.asyncio.AsyncIOLoop object at 0x1554c9a5baf0>>, <Task finished name='Task-423' coro=<Worker.heartbeat() done, defined at /home/ntolley/anaconda3/envs/sbi/lib/python3.8/site-packages/distributed/worker.py:930> exception=OSError('Timed out during handshake while connecting to tcp://198.202.103.184:34547 after 10 s')>)
Traceback (most recent call last):
  File "/home/ntolley/anaconda3/envs/sbi/lib/python3.8/site-packages/tornado/iostream.py", line 867, in _read_to_buffer
    bytes_read = self.read_from_fd(buf)
  File "/home/ntolley/anaconda3/envs/sbi/lib/python3.8/site-packages/tornado/iostream.py", line 1140, in read_from_fd
    return self.socket.recv_into(buf, len(buf))
ConnectionResetError: [Errno 104] Connection reset by peer

The above exception was the direct cause of the following exception:

Traceback (most recent call last):
  File "/home/ntolley/anaconda3/envs/sbi/lib/python3.8/site-packages/distributed/comm/core.py", line 319, in connect
    handshake = await asyncio.wait_for(comm.read(), time_left())
  File "/home/ntolley/anaconda3/envs/sbi/lib/python3.8/asyncio/tasks.py", line 491, in wait_for
    return fut.result()
  File "/home/ntolley/anaconda3/envs/sbi/lib/python3.8/site-packages/distributed/comm/tcp.py", line 202, in read
    convert_stream_closed_error(self, e)
  File "/home/ntolley/anaconda3/envs/sbi/lib/python3.8/site-packages/distributed/comm/tcp.py", line 122, in convert_stream_closed_error
    raise CommClosedError(
distributed.comm.core.CommClosedError: in <closed TCP>: ConnectionResetError: [Errno 104] Connection reset by peer

The above exception was the direct cause of the following exception:

Traceback (most recent call last):
  File "/home/ntolley/anaconda3/envs/sbi/lib/python3.8/site-packages/tornado/ioloop.py", line 741, in _run_callback
    ret = callback()
  File "/home/ntolley/anaconda3/envs/sbi/lib/python3.8/site-packages/tornado/ioloop.py", line 765, in _discard_future_result
    future.result()
  File "/home/ntolley/anaconda3/envs/sbi/lib/python3.8/site-packages/distributed/worker.py", line 976, in heartbeat
    raise e
  File "/home/ntolley/anaconda3/envs/sbi/lib/python3.8/site-packages/distributed/worker.py", line 936, in heartbeat
    response = await retry_operation(
  File "/home/ntolley/anaconda3/envs/sbi/lib/python3.8/site-packages/distributed/utils_comm.py", line 384, in retry_operation
    return await retry(
  File "/home/ntolley/anaconda3/envs/sbi/lib/python3.8/site-packages/distributed/utils_comm.py", line 369, in retry
    return await coro()
  File "/home/ntolley/anaconda3/envs/sbi/lib/python3.8/site-packages/distributed/core.py", line 855, in send_recv_from_rpc
    comm = await self.pool.connect(self.addr)
  File "/home/ntolley/anaconda3/envs/sbi/lib/python3.8/site-packages/distributed/core.py", line 1006, in connect
    comm = await connect(
  File "/home/ntolley/anaconda3/envs/sbi/lib/python3.8/site-packages/distributed/comm/core.py", line 324, in connect
    raise IOError(
OSError: Timed out during handshake while connecting to tcp://198.202.103.184:34547 after 10 s
tornado.application - ERROR - Exception in callback functools.partial(<bound method IOLoop._discard_future_result of <tornado.platform.asyncio.AsyncIOLoop object at 0x1554c9a5aaf0>>, <Task finished name='Task-410' coro=<Worker.heartbeat() done, defined at /home/ntolley/anaconda3/envs/sbi/lib/python3.8/site-packages/distributed/worker.py:930> exception=OSError('Timed out during handshake while connecting to tcp://198.202.103.184:34547 after 10 s')>)
Traceback (most recent call last):
  File "/home/ntolley/anaconda3/envs/sbi/lib/python3.8/site-packages/tornado/iostream.py", line 867, in _read_to_buffer
    bytes_read = self.read_from_fd(buf)
  File "/home/ntolley/anaconda3/envs/sbi/lib/python3.8/site-packages/tornado/iostream.py", line 1140, in read_from_fd
    return self.socket.recv_into(buf, len(buf))
ConnectionResetError: [Errno 104] Connection reset by peer

The above exception was the direct cause of the following exception:

Traceback (most recent call last):
  File "/home/ntolley/anaconda3/envs/sbi/lib/python3.8/site-packages/distributed/comm/core.py", line 319, in connect
    handshake = await asyncio.wait_for(comm.read(), time_left())
  File "/home/ntolley/anaconda3/envs/sbi/lib/python3.8/asyncio/tasks.py", line 491, in wait_for
    return fut.result()
  File "/home/ntolley/anaconda3/envs/sbi/lib/python3.8/site-packages/distributed/comm/tcp.py", line 202, in read
    convert_stream_closed_error(self, e)
  File "/home/ntolley/anaconda3/envs/sbi/lib/python3.8/site-packages/distributed/comm/tcp.py", line 122, in convert_stream_closed_error
    raise CommClosedError(
distributed.comm.core.CommClosedError: in <closed TCP>: ConnectionResetError: [Errno 104] Connection reset by peer

The above exception was the direct cause of the following exception:

Traceback (most recent call last):
  File "/home/ntolley/anaconda3/envs/sbi/lib/python3.8/site-packages/tornado/ioloop.py", line 741, in _run_callback
    ret = callback()
  File "/home/ntolley/anaconda3/envs/sbi/lib/python3.8/site-packages/tornado/ioloop.py", line 765, in _discard_future_result
    future.result()
  File "/home/ntolley/anaconda3/envs/sbi/lib/python3.8/site-packages/distributed/worker.py", line 976, in heartbeat
    raise e
  File "/home/ntolley/anaconda3/envs/sbi/lib/python3.8/site-packages/distributed/worker.py", line 936, in heartbeat
    response = await retry_operation(
  File "/home/ntolley/anaconda3/envs/sbi/lib/python3.8/site-packages/distributed/utils_comm.py", line 384, in retry_operation
    return await retry(
  File "/home/ntolley/anaconda3/envs/sbi/lib/python3.8/site-packages/distributed/utils_comm.py", line 369, in retry
    return await coro()
  File "/home/ntolley/anaconda3/envs/sbi/lib/python3.8/site-packages/distributed/core.py", line 855, in send_recv_from_rpc
    comm = await self.pool.connect(self.addr)
  File "/home/ntolley/anaconda3/envs/sbi/lib/python3.8/site-packages/distributed/core.py", line 1006, in connect
    comm = await connect(
  File "/home/ntolley/anaconda3/envs/sbi/lib/python3.8/site-packages/distributed/comm/core.py", line 324, in connect
    raise IOError(
OSError: Timed out during handshake while connecting to tcp://198.202.103.184:34547 after 10 s
tornado.application - ERROR - Exception in callback functools.partial(<bound method IOLoop._discard_future_result of <tornado.platform.asyncio.AsyncIOLoop object at 0x1554c9a5baf0>>, <Task finished name='Task-410' coro=<Worker.heartbeat() done, defined at /home/ntolley/anaconda3/envs/sbi/lib/python3.8/site-packages/distributed/worker.py:930> exception=OSError('Timed out during handshake while connecting to tcp://198.202.103.184:34547 after 10 s')>)
Traceback (most recent call last):
  File "/home/ntolley/anaconda3/envs/sbi/lib/python3.8/site-packages/tornado/iostream.py", line 867, in _read_to_buffer
    bytes_read = self.read_from_fd(buf)
  File "/home/ntolley/anaconda3/envs/sbi/lib/python3.8/site-packages/tornado/iostream.py", line 1140, in read_from_fd
    return self.socket.recv_into(buf, len(buf))
ConnectionResetError: [Errno 104] Connection reset by peer

The above exception was the direct cause of the following exception:

Traceback (most recent call last):
  File "/home/ntolley/anaconda3/envs/sbi/lib/python3.8/site-packages/distributed/comm/core.py", line 319, in connect
    handshake = await asyncio.wait_for(comm.read(), time_left())
  File "/home/ntolley/anaconda3/envs/sbi/lib/python3.8/asyncio/tasks.py", line 491, in wait_for
    return fut.result()
  File "/home/ntolley/anaconda3/envs/sbi/lib/python3.8/site-packages/distributed/comm/tcp.py", line 202, in read
    convert_stream_closed_error(self, e)
  File "/home/ntolley/anaconda3/envs/sbi/lib/python3.8/site-packages/distributed/comm/tcp.py", line 122, in convert_stream_closed_error
    raise CommClosedError(
distributed.comm.core.CommClosedError: in <closed TCP>: ConnectionResetError: [Errno 104] Connection reset by peer

The above exception was the direct cause of the following exception:

Traceback (most recent call last):
  File "/home/ntolley/anaconda3/envs/sbi/lib/python3.8/site-packages/tornado/ioloop.py", line 741, in _run_callback
    ret = callback()
  File "/home/ntolley/anaconda3/envs/sbi/lib/python3.8/site-packages/tornado/ioloop.py", line 765, in _discard_future_result
    future.result()
  File "/home/ntolley/anaconda3/envs/sbi/lib/python3.8/site-packages/distributed/worker.py", line 976, in heartbeat
    raise e
  File "/home/ntolley/anaconda3/envs/sbi/lib/python3.8/site-packages/distributed/worker.py", line 936, in heartbeat
    response = await retry_operation(
  File "/home/ntolley/anaconda3/envs/sbi/lib/python3.8/site-packages/distributed/utils_comm.py", line 384, in retry_operation
    return await retry(
  File "/home/ntolley/anaconda3/envs/sbi/lib/python3.8/site-packages/distributed/utils_comm.py", line 369, in retry
    return await coro()
  File "/home/ntolley/anaconda3/envs/sbi/lib/python3.8/site-packages/distributed/core.py", line 855, in send_recv_from_rpc
    comm = await self.pool.connect(self.addr)
  File "/home/ntolley/anaconda3/envs/sbi/lib/python3.8/site-packages/distributed/core.py", line 1006, in connect
    comm = await connect(
  File "/home/ntolley/anaconda3/envs/sbi/lib/python3.8/site-packages/distributed/comm/core.py", line 324, in connect
    raise IOError(
OSError: Timed out during handshake while connecting to tcp://198.202.103.184:34547 after 10 s
tornado.application - ERROR - Exception in callback functools.partial(<bound method IOLoop._discard_future_result of <tornado.platform.asyncio.AsyncIOLoop object at 0x1554c9a5baf0>>, <Task finished name='Task-423' coro=<Worker.heartbeat() done, defined at /home/ntolley/anaconda3/envs/sbi/lib/python3.8/site-packages/distributed/worker.py:930> exception=OSError('Timed out during handshake while connecting to tcp://198.202.103.184:34547 after 10 s')>)
Traceback (most recent call last):
  File "/home/ntolley/anaconda3/envs/sbi/lib/python3.8/site-packages/tornado/iostream.py", line 867, in _read_to_buffer
    bytes_read = self.read_from_fd(buf)
  File "/home/ntolley/anaconda3/envs/sbi/lib/python3.8/site-packages/tornado/iostream.py", line 1140, in read_from_fd
    return self.socket.recv_into(buf, len(buf))
ConnectionResetError: [Errno 104] Connection reset by peer

The above exception was the direct cause of the following exception:

Traceback (most recent call last):
  File "/home/ntolley/anaconda3/envs/sbi/lib/python3.8/site-packages/distributed/comm/core.py", line 319, in connect
    handshake = await asyncio.wait_for(comm.read(), time_left())
  File "/home/ntolley/anaconda3/envs/sbi/lib/python3.8/asyncio/tasks.py", line 491, in wait_for
    return fut.result()
  File "/home/ntolley/anaconda3/envs/sbi/lib/python3.8/site-packages/distributed/comm/tcp.py", line 202, in read
    convert_stream_closed_error(self, e)
  File "/home/ntolley/anaconda3/envs/sbi/lib/python3.8/site-packages/distributed/comm/tcp.py", line 122, in convert_stream_closed_error
    raise CommClosedError(
distributed.comm.core.CommClosedError: in <closed TCP>: ConnectionResetError: [Errno 104] Connection reset by peer

The above exception was the direct cause of the following exception:

Traceback (most recent call last):
  File "/home/ntolley/anaconda3/envs/sbi/lib/python3.8/site-packages/tornado/ioloop.py", line 741, in _run_callback
    ret = callback()
  File "/home/ntolley/anaconda3/envs/sbi/lib/python3.8/site-packages/tornado/ioloop.py", line 765, in _discard_future_result
    future.result()
  File "/home/ntolley/anaconda3/envs/sbi/lib/python3.8/site-packages/distributed/worker.py", line 976, in heartbeat
    raise e
  File "/home/ntolley/anaconda3/envs/sbi/lib/python3.8/site-packages/distributed/worker.py", line 936, in heartbeat
    response = await retry_operation(
  File "/home/ntolley/anaconda3/envs/sbi/lib/python3.8/site-packages/distributed/utils_comm.py", line 384, in retry_operation
    return await retry(
  File "/home/ntolley/anaconda3/envs/sbi/lib/python3.8/site-packages/distributed/utils_comm.py", line 369, in retry
    return await coro()
  File "/home/ntolley/anaconda3/envs/sbi/lib/python3.8/site-packages/distributed/core.py", line 855, in send_recv_from_rpc
    comm = await self.pool.connect(self.addr)
  File "/home/ntolley/anaconda3/envs/sbi/lib/python3.8/site-packages/distributed/core.py", line 1006, in connect
    comm = await connect(
  File "/home/ntolley/anaconda3/envs/sbi/lib/python3.8/site-packages/distributed/comm/core.py", line 324, in connect
    raise IOError(
OSError: Timed out during handshake while connecting to tcp://198.202.103.184:34547 after 10 s
tornado.application - ERROR - Exception in callback functools.partial(<bound method IOLoop._discard_future_result of <tornado.platform.asyncio.AsyncIOLoop object at 0x1554c9a5baf0>>, <Task finished name='Task-422' coro=<Worker.heartbeat() done, defined at /home/ntolley/anaconda3/envs/sbi/lib/python3.8/site-packages/distributed/worker.py:930> exception=OSError('Timed out during handshake while connecting to tcp://198.202.103.184:34547 after 10 s')>)
Traceback (most recent call last):
  File "/home/ntolley/anaconda3/envs/sbi/lib/python3.8/site-packages/tornado/iostream.py", line 867, in _read_to_buffer
    bytes_read = self.read_from_fd(buf)
  File "/home/ntolley/anaconda3/envs/sbi/lib/python3.8/site-packages/tornado/iostream.py", line 1140, in read_from_fd
    return self.socket.recv_into(buf, len(buf))
ConnectionResetError: [Errno 104] Connection reset by peer

The above exception was the direct cause of the following exception:

Traceback (most recent call last):
  File "/home/ntolley/anaconda3/envs/sbi/lib/python3.8/site-packages/distributed/comm/core.py", line 319, in connect
    handshake = await asyncio.wait_for(comm.read(), time_left())
  File "/home/ntolley/anaconda3/envs/sbi/lib/python3.8/asyncio/tasks.py", line 491, in wait_for
    return fut.result()
  File "/home/ntolley/anaconda3/envs/sbi/lib/python3.8/site-packages/distributed/comm/tcp.py", line 202, in read
    convert_stream_closed_error(self, e)
  File "/home/ntolley/anaconda3/envs/sbi/lib/python3.8/site-packages/distributed/comm/tcp.py", line 122, in convert_stream_closed_error
    raise CommClosedError(
distributed.comm.core.CommClosedError: in <closed TCP>: ConnectionResetError: [Errno 104] Connection reset by peer

The above exception was the direct cause of the following exception:

Traceback (most recent call last):
  File "/home/ntolley/anaconda3/envs/sbi/lib/python3.8/site-packages/tornado/ioloop.py", line 741, in _run_callback
    ret = callback()
  File "/home/ntolley/anaconda3/envs/sbi/lib/python3.8/site-packages/tornado/ioloop.py", line 765, in _discard_future_result
    future.result()
  File "/home/ntolley/anaconda3/envs/sbi/lib/python3.8/site-packages/distributed/worker.py", line 976, in heartbeat
    raise e
  File "/home/ntolley/anaconda3/envs/sbi/lib/python3.8/site-packages/distributed/worker.py", line 936, in heartbeat
    response = await retry_operation(
  File "/home/ntolley/anaconda3/envs/sbi/lib/python3.8/site-packages/distributed/utils_comm.py", line 384, in retry_operation
    return await retry(
  File "/home/ntolley/anaconda3/envs/sbi/lib/python3.8/site-packages/distributed/utils_comm.py", line 369, in retry
    return await coro()
  File "/home/ntolley/anaconda3/envs/sbi/lib/python3.8/site-packages/distributed/core.py", line 855, in send_recv_from_rpc
    comm = await self.pool.connect(self.addr)
  File "/home/ntolley/anaconda3/envs/sbi/lib/python3.8/site-packages/distributed/core.py", line 1006, in connect
    comm = await connect(
  File "/home/ntolley/anaconda3/envs/sbi/lib/python3.8/site-packages/distributed/comm/core.py", line 324, in connect
    raise IOError(
OSError: Timed out during handshake while connecting to tcp://198.202.103.184:34547 after 10 s
tornado.application - ERROR - Exception in callback functools.partial(<bound method IOLoop._discard_future_result of <tornado.platform.asyncio.AsyncIOLoop object at 0x1554c9a5baf0>>, <Task finished name='Task-403' coro=<Worker.heartbeat() done, defined at /home/ntolley/anaconda3/envs/sbi/lib/python3.8/site-packages/distributed/worker.py:930> exception=OSError('Timed out during handshake while connecting to tcp://198.202.103.184:34547 after 10 s')>)
Traceback (most recent call last):
  File "/home/ntolley/anaconda3/envs/sbi/lib/python3.8/site-packages/tornado/iostream.py", line 867, in _read_to_buffer
    bytes_read = self.read_from_fd(buf)
  File "/home/ntolley/anaconda3/envs/sbi/lib/python3.8/site-packages/tornado/iostream.py", line 1140, in read_from_fd
    return self.socket.recv_into(buf, len(buf))
ConnectionResetError: [Errno 104] Connection reset by peer

The above exception was the direct cause of the following exception:

Traceback (most recent call last):
  File "/home/ntolley/anaconda3/envs/sbi/lib/python3.8/site-packages/distributed/comm/core.py", line 319, in connect
    handshake = await asyncio.wait_for(comm.read(), time_left())
  File "/home/ntolley/anaconda3/envs/sbi/lib/python3.8/asyncio/tasks.py", line 491, in wait_for
    return fut.result()
  File "/home/ntolley/anaconda3/envs/sbi/lib/python3.8/site-packages/distributed/comm/tcp.py", line 202, in read
    convert_stream_closed_error(self, e)
  File "/home/ntolley/anaconda3/envs/sbi/lib/python3.8/site-packages/distributed/comm/tcp.py", line 122, in convert_stream_closed_error
    raise CommClosedError(
distributed.comm.core.CommClosedError: in <closed TCP>: ConnectionResetError: [Errno 104] Connection reset by peer

The above exception was the direct cause of the following exception:

Traceback (most recent call last):
  File "/home/ntolley/anaconda3/envs/sbi/lib/python3.8/site-packages/tornado/ioloop.py", line 741, in _run_callback
    ret = callback()
  File "/home/ntolley/anaconda3/envs/sbi/lib/python3.8/site-packages/tornado/ioloop.py", line 765, in _discard_future_result
    future.result()
  File "/home/ntolley/anaconda3/envs/sbi/lib/python3.8/site-packages/distributed/worker.py", line 976, in heartbeat
    raise e
  File "/home/ntolley/anaconda3/envs/sbi/lib/python3.8/site-packages/distributed/worker.py", line 936, in heartbeat
    response = await retry_operation(
  File "/home/ntolley/anaconda3/envs/sbi/lib/python3.8/site-packages/distributed/utils_comm.py", line 384, in retry_operation
    return await retry(
  File "/home/ntolley/anaconda3/envs/sbi/lib/python3.8/site-packages/distributed/utils_comm.py", line 369, in retry
    return await coro()
  File "/home/ntolley/anaconda3/envs/sbi/lib/python3.8/site-packages/distributed/core.py", line 855, in send_recv_from_rpc
    comm = await self.pool.connect(self.addr)
  File "/home/ntolley/anaconda3/envs/sbi/lib/python3.8/site-packages/distributed/core.py", line 1006, in connect
    comm = await connect(
  File "/home/ntolley/anaconda3/envs/sbi/lib/python3.8/site-packages/distributed/comm/core.py", line 324, in connect
    raise IOError(
OSError: Timed out during handshake while connecting to tcp://198.202.103.184:34547 after 10 s
tornado.application - ERROR - Exception in callback functools.partial(<bound method IOLoop._discard_future_result of <tornado.platform.asyncio.AsyncIOLoop object at 0x1554c9a5aaf0>>, <Task finished name='Task-410' coro=<Worker.heartbeat() done, defined at /home/ntolley/anaconda3/envs/sbi/lib/python3.8/site-packages/distributed/worker.py:930> exception=OSError('Timed out during handshake while connecting to tcp://198.202.103.184:34547 after 10 s')>)
Traceback (most recent call last):
  File "/home/ntolley/anaconda3/envs/sbi/lib/python3.8/site-packages/tornado/iostream.py", line 867, in _read_to_buffer
    bytes_read = self.read_from_fd(buf)
  File "/home/ntolley/anaconda3/envs/sbi/lib/python3.8/site-packages/tornado/iostream.py", line 1140, in read_from_fd
    return self.socket.recv_into(buf, len(buf))
ConnectionResetError: [Errno 104] Connection reset by peer

The above exception was the direct cause of the following exception:

Traceback (most recent call last):
  File "/home/ntolley/anaconda3/envs/sbi/lib/python3.8/site-packages/distributed/comm/core.py", line 319, in connect
    handshake = await asyncio.wait_for(comm.read(), time_left())
  File "/home/ntolley/anaconda3/envs/sbi/lib/python3.8/asyncio/tasks.py", line 491, in wait_for
    return fut.result()
  File "/home/ntolley/anaconda3/envs/sbi/lib/python3.8/site-packages/distributed/comm/tcp.py", line 202, in read
    convert_stream_closed_error(self, e)
  File "/home/ntolley/anaconda3/envs/sbi/lib/python3.8/site-packages/distributed/comm/tcp.py", line 122, in convert_stream_closed_error
    raise CommClosedError(
distributed.comm.core.CommClosedError: in <closed TCP>: ConnectionResetError: [Errno 104] Connection reset by peer

The above exception was the direct cause of the following exception:

Traceback (most recent call last):
  File "/home/ntolley/anaconda3/envs/sbi/lib/python3.8/site-packages/tornado/ioloop.py", line 741, in _run_callback
    ret = callback()
  File "/home/ntolley/anaconda3/envs/sbi/lib/python3.8/site-packages/tornado/ioloop.py", line 765, in _discard_future_result
    future.result()
  File "/home/ntolley/anaconda3/envs/sbi/lib/python3.8/site-packages/distributed/worker.py", line 976, in heartbeat
    raise e
  File "/home/ntolley/anaconda3/envs/sbi/lib/python3.8/site-packages/distributed/worker.py", line 936, in heartbeat
    response = await retry_operation(
  File "/home/ntolley/anaconda3/envs/sbi/lib/python3.8/site-packages/distributed/utils_comm.py", line 384, in retry_operation
    return await retry(
  File "/home/ntolley/anaconda3/envs/sbi/lib/python3.8/site-packages/distributed/utils_comm.py", line 369, in retry
    return await coro()
  File "/home/ntolley/anaconda3/envs/sbi/lib/python3.8/site-packages/distributed/core.py", line 855, in send_recv_from_rpc
    comm = await self.pool.connect(self.addr)
  File "/home/ntolley/anaconda3/envs/sbi/lib/python3.8/site-packages/distributed/core.py", line 1006, in connect
    comm = await connect(
  File "/home/ntolley/anaconda3/envs/sbi/lib/python3.8/site-packages/distributed/comm/core.py", line 324, in connect
    raise IOError(
OSError: Timed out during handshake while connecting to tcp://198.202.103.184:34547 after 10 s
tornado.application - ERROR - Exception in callback functools.partial(<bound method IOLoop._discard_future_result of <tornado.platform.asyncio.AsyncIOLoop object at 0x1554c9a5baf0>>, <Task finished name='Task-404' coro=<Worker.heartbeat() done, defined at /home/ntolley/anaconda3/envs/sbi/lib/python3.8/site-packages/distributed/worker.py:930> exception=OSError('Timed out during handshake while connecting to tcp://198.202.103.184:34547 after 10 s')>)
Traceback (most recent call last):
  File "/home/ntolley/anaconda3/envs/sbi/lib/python3.8/site-packages/tornado/iostream.py", line 867, in _read_to_buffer
    bytes_read = self.read_from_fd(buf)
  File "/home/ntolley/anaconda3/envs/sbi/lib/python3.8/site-packages/tornado/iostream.py", line 1140, in read_from_fd
    return self.socket.recv_into(buf, len(buf))
ConnectionResetError: [Errno 104] Connection reset by peer

The above exception was the direct cause of the following exception:

Traceback (most recent call last):
  File "/home/ntolley/anaconda3/envs/sbi/lib/python3.8/site-packages/distributed/comm/core.py", line 319, in connect
    handshake = await asyncio.wait_for(comm.read(), time_left())
  File "/home/ntolley/anaconda3/envs/sbi/lib/python3.8/asyncio/tasks.py", line 491, in wait_for
    return fut.result()
  File "/home/ntolley/anaconda3/envs/sbi/lib/python3.8/site-packages/distributed/comm/tcp.py", line 202, in read
    convert_stream_closed_error(self, e)
  File "/home/ntolley/anaconda3/envs/sbi/lib/python3.8/site-packages/distributed/comm/tcp.py", line 122, in convert_stream_closed_error
    raise CommClosedError(
distributed.comm.core.CommClosedError: in <closed TCP>: ConnectionResetError: [Errno 104] Connection reset by peer

The above exception was the direct cause of the following exception:

Traceback (most recent call last):
  File "/home/ntolley/anaconda3/envs/sbi/lib/python3.8/site-packages/tornado/ioloop.py", line 741, in _run_callback
    ret = callback()
  File "/home/ntolley/anaconda3/envs/sbi/lib/python3.8/site-packages/tornado/ioloop.py", line 765, in _discard_future_result
    future.result()
  File "/home/ntolley/anaconda3/envs/sbi/lib/python3.8/site-packages/distributed/worker.py", line 976, in heartbeat
    raise e
  File "/home/ntolley/anaconda3/envs/sbi/lib/python3.8/site-packages/distributed/worker.py", line 936, in heartbeat
    response = await retry_operation(
  File "/home/ntolley/anaconda3/envs/sbi/lib/python3.8/site-packages/distributed/utils_comm.py", line 384, in retry_operation
    return await retry(
  File "/home/ntolley/anaconda3/envs/sbi/lib/python3.8/site-packages/distributed/utils_comm.py", line 369, in retry
    return await coro()
  File "/home/ntolley/anaconda3/envs/sbi/lib/python3.8/site-packages/distributed/core.py", line 855, in send_recv_from_rpc
    comm = await self.pool.connect(self.addr)
  File "/home/ntolley/anaconda3/envs/sbi/lib/python3.8/site-packages/distributed/core.py", line 1006, in connect
    comm = await connect(
  File "/home/ntolley/anaconda3/envs/sbi/lib/python3.8/site-packages/distributed/comm/core.py", line 324, in connect
    raise IOError(
OSError: Timed out during handshake while connecting to tcp://198.202.103.184:34547 after 10 s
tornado.application - ERROR - Exception in callback functools.partial(<bound method IOLoop._discard_future_result of <tornado.platform.asyncio.AsyncIOLoop object at 0x1554c9a5baf0>>, <Task finished name='Task-405' coro=<Worker.heartbeat() done, defined at /home/ntolley/anaconda3/envs/sbi/lib/python3.8/site-packages/distributed/worker.py:930> exception=OSError('Timed out during handshake while connecting to tcp://198.202.103.184:34547 after 10 s')>)
Traceback (most recent call last):
  File "/home/ntolley/anaconda3/envs/sbi/lib/python3.8/site-packages/tornado/iostream.py", line 867, in _read_to_buffer
    bytes_read = self.read_from_fd(buf)
  File "/home/ntolley/anaconda3/envs/sbi/lib/python3.8/site-packages/tornado/iostream.py", line 1140, in read_from_fd
    return self.socket.recv_into(buf, len(buf))
ConnectionResetError: [Errno 104] Connection reset by peer

The above exception was the direct cause of the following exception:

Traceback (most recent call last):
  File "/home/ntolley/anaconda3/envs/sbi/lib/python3.8/site-packages/distributed/comm/core.py", line 319, in connect
    handshake = await asyncio.wait_for(comm.read(), time_left())
  File "/home/ntolley/anaconda3/envs/sbi/lib/python3.8/asyncio/tasks.py", line 491, in wait_for
    return fut.result()
  File "/home/ntolley/anaconda3/envs/sbi/lib/python3.8/site-packages/distributed/comm/tcp.py", line 202, in read
    convert_stream_closed_error(self, e)
  File "/home/ntolley/anaconda3/envs/sbi/lib/python3.8/site-packages/distributed/comm/tcp.py", line 122, in convert_stream_closed_error
    raise CommClosedError(
distributed.comm.core.CommClosedError: in <closed TCP>: ConnectionResetError: [Errno 104] Connection reset by peer

The above exception was the direct cause of the following exception:

Traceback (most recent call last):
  File "/home/ntolley/anaconda3/envs/sbi/lib/python3.8/site-packages/tornado/ioloop.py", line 741, in _run_callback
    ret = callback()
  File "/home/ntolley/anaconda3/envs/sbi/lib/python3.8/site-packages/tornado/ioloop.py", line 765, in _discard_future_result
    future.result()
  File "/home/ntolley/anaconda3/envs/sbi/lib/python3.8/site-packages/distributed/worker.py", line 976, in heartbeat
    raise e
  File "/home/ntolley/anaconda3/envs/sbi/lib/python3.8/site-packages/distributed/worker.py", line 936, in heartbeat
    response = await retry_operation(
  File "/home/ntolley/anaconda3/envs/sbi/lib/python3.8/site-packages/distributed/utils_comm.py", line 384, in retry_operation
    return await retry(
  File "/home/ntolley/anaconda3/envs/sbi/lib/python3.8/site-packages/distributed/utils_comm.py", line 369, in retry
    return await coro()
  File "/home/ntolley/anaconda3/envs/sbi/lib/python3.8/site-packages/distributed/core.py", line 855, in send_recv_from_rpc
    comm = await self.pool.connect(self.addr)
  File "/home/ntolley/anaconda3/envs/sbi/lib/python3.8/site-packages/distributed/core.py", line 1006, in connect
    comm = await connect(
  File "/home/ntolley/anaconda3/envs/sbi/lib/python3.8/site-packages/distributed/comm/core.py", line 324, in connect
    raise IOError(
OSError: Timed out during handshake while connecting to tcp://198.202.103.184:34547 after 10 s
tornado.application - ERROR - Exception in callback functools.partial(<bound method IOLoop._discard_future_result of <tornado.platform.asyncio.AsyncIOLoop object at 0x1554c9a5baf0>>, <Task finished name='Task-422' coro=<Worker.heartbeat() done, defined at /home/ntolley/anaconda3/envs/sbi/lib/python3.8/site-packages/distributed/worker.py:930> exception=OSError('Timed out during handshake while connecting to tcp://198.202.103.184:34547 after 10 s')>)
Traceback (most recent call last):
  File "/home/ntolley/anaconda3/envs/sbi/lib/python3.8/site-packages/tornado/iostream.py", line 867, in _read_to_buffer
    bytes_read = self.read_from_fd(buf)
  File "/home/ntolley/anaconda3/envs/sbi/lib/python3.8/site-packages/tornado/iostream.py", line 1140, in read_from_fd
    return self.socket.recv_into(buf, len(buf))
ConnectionResetError: [Errno 104] Connection reset by peer

The above exception was the direct cause of the following exception:

Traceback (most recent call last):
  File "/home/ntolley/anaconda3/envs/sbi/lib/python3.8/site-packages/distributed/comm/core.py", line 319, in connect
    handshake = await asyncio.wait_for(comm.read(), time_left())
  File "/home/ntolley/anaconda3/envs/sbi/lib/python3.8/asyncio/tasks.py", line 491, in wait_for
    return fut.result()
  File "/home/ntolley/anaconda3/envs/sbi/lib/python3.8/site-packages/distributed/comm/tcp.py", line 202, in read
    convert_stream_closed_error(self, e)
  File "/home/ntolley/anaconda3/envs/sbi/lib/python3.8/site-packages/distributed/comm/tcp.py", line 122, in convert_stream_closed_error
    raise CommClosedError(
distributed.comm.core.CommClosedError: in <closed TCP>: ConnectionResetError: [Errno 104] Connection reset by peer

The above exception was the direct cause of the following exception:

Traceback (most recent call last):
  File "/home/ntolley/anaconda3/envs/sbi/lib/python3.8/site-packages/tornado/ioloop.py", line 741, in _run_callback
    ret = callback()
  File "/home/ntolley/anaconda3/envs/sbi/lib/python3.8/site-packages/tornado/ioloop.py", line 765, in _discard_future_result
    future.result()
  File "/home/ntolley/anaconda3/envs/sbi/lib/python3.8/site-packages/distributed/worker.py", line 976, in heartbeat
    raise e
  File "/home/ntolley/anaconda3/envs/sbi/lib/python3.8/site-packages/distributed/worker.py", line 936, in heartbeat
    response = await retry_operation(
  File "/home/ntolley/anaconda3/envs/sbi/lib/python3.8/site-packages/distributed/utils_comm.py", line 384, in retry_operation
    return await retry(
  File "/home/ntolley/anaconda3/envs/sbi/lib/python3.8/site-packages/distributed/utils_comm.py", line 369, in retry
    return await coro()
  File "/home/ntolley/anaconda3/envs/sbi/lib/python3.8/site-packages/distributed/core.py", line 855, in send_recv_from_rpc
    comm = await self.pool.connect(self.addr)
  File "/home/ntolley/anaconda3/envs/sbi/lib/python3.8/site-packages/distributed/core.py", line 1006, in connect
    comm = await connect(
  File "/home/ntolley/anaconda3/envs/sbi/lib/python3.8/site-packages/distributed/comm/core.py", line 324, in connect
    raise IOError(
OSError: Timed out during handshake while connecting to tcp://198.202.103.184:34547 after 10 s
tornado.application - ERROR - Exception in callback functools.partial(<bound method IOLoop._discard_future_result of <tornado.platform.asyncio.AsyncIOLoop object at 0x1554c9a5baf0>>, <Task finished name='Task-405' coro=<Worker.heartbeat() done, defined at /home/ntolley/anaconda3/envs/sbi/lib/python3.8/site-packages/distributed/worker.py:930> exception=OSError('Timed out during handshake while connecting to tcp://198.202.103.184:34547 after 10 s')>)
Traceback (most recent call last):
  File "/home/ntolley/anaconda3/envs/sbi/lib/python3.8/site-packages/tornado/iostream.py", line 867, in _read_to_buffer
    bytes_read = self.read_from_fd(buf)
  File "/home/ntolley/anaconda3/envs/sbi/lib/python3.8/site-packages/tornado/iostream.py", line 1140, in read_from_fd
    return self.socket.recv_into(buf, len(buf))
ConnectionResetError: [Errno 104] Connection reset by peer

The above exception was the direct cause of the following exception:

Traceback (most recent call last):
  File "/home/ntolley/anaconda3/envs/sbi/lib/python3.8/site-packages/distributed/comm/core.py", line 319, in connect
    handshake = await asyncio.wait_for(comm.read(), time_left())
  File "/home/ntolley/anaconda3/envs/sbi/lib/python3.8/asyncio/tasks.py", line 491, in wait_for
    return fut.result()
  File "/home/ntolley/anaconda3/envs/sbi/lib/python3.8/site-packages/distributed/comm/tcp.py", line 202, in read
    convert_stream_closed_error(self, e)
  File "/home/ntolley/anaconda3/envs/sbi/lib/python3.8/site-packages/distributed/comm/tcp.py", line 122, in convert_stream_closed_error
    raise CommClosedError(
distributed.comm.core.CommClosedError: in <closed TCP>: ConnectionResetError: [Errno 104] Connection reset by peer

The above exception was the direct cause of the following exception:

Traceback (most recent call last):
  File "/home/ntolley/anaconda3/envs/sbi/lib/python3.8/site-packages/tornado/ioloop.py", line 741, in _run_callback
    ret = callback()
  File "/home/ntolley/anaconda3/envs/sbi/lib/python3.8/site-packages/tornado/ioloop.py", line 765, in _discard_future_result
    future.result()
  File "/home/ntolley/anaconda3/envs/sbi/lib/python3.8/site-packages/distributed/worker.py", line 976, in heartbeat
    raise e
  File "/home/ntolley/anaconda3/envs/sbi/lib/python3.8/site-packages/distributed/worker.py", line 936, in heartbeat
    response = await retry_operation(
  File "/home/ntolley/anaconda3/envs/sbi/lib/python3.8/site-packages/distributed/utils_comm.py", line 384, in retry_operation
    return await retry(
  File "/home/ntolley/anaconda3/envs/sbi/lib/python3.8/site-packages/distributed/utils_comm.py", line 369, in retry
    return await coro()
  File "/home/ntolley/anaconda3/envs/sbi/lib/python3.8/site-packages/distributed/core.py", line 855, in send_recv_from_rpc
    comm = await self.pool.connect(self.addr)
  File "/home/ntolley/anaconda3/envs/sbi/lib/python3.8/site-packages/distributed/core.py", line 1006, in connect
    comm = await connect(
  File "/home/ntolley/anaconda3/envs/sbi/lib/python3.8/site-packages/distributed/comm/core.py", line 324, in connect
    raise IOError(
OSError: Timed out during handshake while connecting to tcp://198.202.103.184:34547 after 10 s
tornado.application - ERROR - Exception in callback functools.partial(<bound method IOLoop._discard_future_result of <tornado.platform.asyncio.AsyncIOLoop object at 0x1554c9a5baf0>>, <Task finished name='Task-403' coro=<Worker.heartbeat() done, defined at /home/ntolley/anaconda3/envs/sbi/lib/python3.8/site-packages/distributed/worker.py:930> exception=OSError('Timed out during handshake while connecting to tcp://198.202.103.184:34547 after 10 s')>)
Traceback (most recent call last):
  File "/home/ntolley/anaconda3/envs/sbi/lib/python3.8/site-packages/tornado/iostream.py", line 867, in _read_to_buffer
    bytes_read = self.read_from_fd(buf)
  File "/home/ntolley/anaconda3/envs/sbi/lib/python3.8/site-packages/tornado/iostream.py", line 1140, in read_from_fd
    return self.socket.recv_into(buf, len(buf))
ConnectionResetError: [Errno 104] Connection reset by peer

The above exception was the direct cause of the following exception:

Traceback (most recent call last):
  File "/home/ntolley/anaconda3/envs/sbi/lib/python3.8/site-packages/distributed/comm/core.py", line 319, in connect
    handshake = await asyncio.wait_for(comm.read(), time_left())
  File "/home/ntolley/anaconda3/envs/sbi/lib/python3.8/asyncio/tasks.py", line 491, in wait_for
    return fut.result()
  File "/home/ntolley/anaconda3/envs/sbi/lib/python3.8/site-packages/distributed/comm/tcp.py", line 202, in read
    convert_stream_closed_error(self, e)
  File "/home/ntolley/anaconda3/envs/sbi/lib/python3.8/site-packages/distributed/comm/tcp.py", line 122, in convert_stream_closed_error
    raise CommClosedError(
distributed.comm.core.CommClosedError: in <closed TCP>: ConnectionResetError: [Errno 104] Connection reset by peer

The above exception was the direct cause of the following exception:

Traceback (most recent call last):
  File "/home/ntolley/anaconda3/envs/sbi/lib/python3.8/site-packages/tornado/ioloop.py", line 741, in _run_callback
    ret = callback()
  File "/home/ntolley/anaconda3/envs/sbi/lib/python3.8/site-packages/tornado/ioloop.py", line 765, in _discard_future_result
    future.result()
  File "/home/ntolley/anaconda3/envs/sbi/lib/python3.8/site-packages/distributed/worker.py", line 976, in heartbeat
    raise e
  File "/home/ntolley/anaconda3/envs/sbi/lib/python3.8/site-packages/distributed/worker.py", line 936, in heartbeat
    response = await retry_operation(
  File "/home/ntolley/anaconda3/envs/sbi/lib/python3.8/site-packages/distributed/utils_comm.py", line 384, in retry_operation
    return await retry(
  File "/home/ntolley/anaconda3/envs/sbi/lib/python3.8/site-packages/distributed/utils_comm.py", line 369, in retry
    return await coro()
  File "/home/ntolley/anaconda3/envs/sbi/lib/python3.8/site-packages/distributed/core.py", line 855, in send_recv_from_rpc
    comm = await self.pool.connect(self.addr)
  File "/home/ntolley/anaconda3/envs/sbi/lib/python3.8/site-packages/distributed/core.py", line 1006, in connect
    comm = await connect(
  File "/home/ntolley/anaconda3/envs/sbi/lib/python3.8/site-packages/distributed/comm/core.py", line 324, in connect
    raise IOError(
OSError: Timed out during handshake while connecting to tcp://198.202.103.184:34547 after 10 s
tornado.application - ERROR - Exception in callback functools.partial(<bound method IOLoop._discard_future_result of <tornado.platform.asyncio.AsyncIOLoop object at 0x1554c9a5baf0>>, <Task finished name='Task-421' coro=<Worker.heartbeat() done, defined at /home/ntolley/anaconda3/envs/sbi/lib/python3.8/site-packages/distributed/worker.py:930> exception=OSError('Timed out during handshake while connecting to tcp://198.202.103.184:34547 after 10 s')>)
Traceback (most recent call last):
  File "/home/ntolley/anaconda3/envs/sbi/lib/python3.8/site-packages/tornado/iostream.py", line 867, in _read_to_buffer
    bytes_read = self.read_from_fd(buf)
  File "/home/ntolley/anaconda3/envs/sbi/lib/python3.8/site-packages/tornado/iostream.py", line 1140, in read_from_fd
    return self.socket.recv_into(buf, len(buf))
ConnectionResetError: [Errno 104] Connection reset by peer

The above exception was the direct cause of the following exception:

Traceback (most recent call last):
  File "/home/ntolley/anaconda3/envs/sbi/lib/python3.8/site-packages/distributed/comm/core.py", line 319, in connect
    handshake = await asyncio.wait_for(comm.read(), time_left())
  File "/home/ntolley/anaconda3/envs/sbi/lib/python3.8/asyncio/tasks.py", line 491, in wait_for
    return fut.result()
  File "/home/ntolley/anaconda3/envs/sbi/lib/python3.8/site-packages/distributed/comm/tcp.py", line 202, in read
    convert_stream_closed_error(self, e)
  File "/home/ntolley/anaconda3/envs/sbi/lib/python3.8/site-packages/distributed/comm/tcp.py", line 122, in convert_stream_closed_error
    raise CommClosedError(
distributed.comm.core.CommClosedError: in <closed TCP>: ConnectionResetError: [Errno 104] Connection reset by peer

The above exception was the direct cause of the following exception:

Traceback (most recent call last):
  File "/home/ntolley/anaconda3/envs/sbi/lib/python3.8/site-packages/tornado/ioloop.py", line 741, in _run_callback
    ret = callback()
  File "/home/ntolley/anaconda3/envs/sbi/lib/python3.8/site-packages/tornado/ioloop.py", line 765, in _discard_future_result
    future.result()
  File "/home/ntolley/anaconda3/envs/sbi/lib/python3.8/site-packages/distributed/worker.py", line 976, in heartbeat
    raise e
  File "/home/ntolley/anaconda3/envs/sbi/lib/python3.8/site-packages/distributed/worker.py", line 936, in heartbeat
    response = await retry_operation(
  File "/home/ntolley/anaconda3/envs/sbi/lib/python3.8/site-packages/distributed/utils_comm.py", line 384, in retry_operation
    return await retry(
  File "/home/ntolley/anaconda3/envs/sbi/lib/python3.8/site-packages/distributed/utils_comm.py", line 369, in retry
    return await coro()
  File "/home/ntolley/anaconda3/envs/sbi/lib/python3.8/site-packages/distributed/core.py", line 855, in send_recv_from_rpc
    comm = await self.pool.connect(self.addr)
  File "/home/ntolley/anaconda3/envs/sbi/lib/python3.8/site-packages/distributed/core.py", line 1006, in connect
    comm = await connect(
  File "/home/ntolley/anaconda3/envs/sbi/lib/python3.8/site-packages/distributed/comm/core.py", line 324, in connect
    raise IOError(
OSError: Timed out during handshake while connecting to tcp://198.202.103.184:34547 after 10 s
tornado.application - ERROR - Exception in callback functools.partial(<bound method IOLoop._discard_future_result of <tornado.platform.asyncio.AsyncIOLoop object at 0x1554c9a5baf0>>, <Task finished name='Task-409' coro=<Worker.heartbeat() done, defined at /home/ntolley/anaconda3/envs/sbi/lib/python3.8/site-packages/distributed/worker.py:930> exception=OSError('Timed out during handshake while connecting to tcp://198.202.103.184:34547 after 10 s')>)
Traceback (most recent call last):
  File "/home/ntolley/anaconda3/envs/sbi/lib/python3.8/site-packages/tornado/iostream.py", line 867, in _read_to_buffer
    bytes_read = self.read_from_fd(buf)
  File "/home/ntolley/anaconda3/envs/sbi/lib/python3.8/site-packages/tornado/iostream.py", line 1140, in read_from_fd
    return self.socket.recv_into(buf, len(buf))
ConnectionResetError: [Errno 104] Connection reset by peer

The above exception was the direct cause of the following exception:

Traceback (most recent call last):
  File "/home/ntolley/anaconda3/envs/sbi/lib/python3.8/site-packages/distributed/comm/core.py", line 319, in connect
    handshake = await asyncio.wait_for(comm.read(), time_left())
  File "/home/ntolley/anaconda3/envs/sbi/lib/python3.8/asyncio/tasks.py", line 491, in wait_for
    return fut.result()
  File "/home/ntolley/anaconda3/envs/sbi/lib/python3.8/site-packages/distributed/comm/tcp.py", line 202, in read
    convert_stream_closed_error(self, e)
  File "/home/ntolley/anaconda3/envs/sbi/lib/python3.8/site-packages/distributed/comm/tcp.py", line 122, in convert_stream_closed_error
    raise CommClosedError(
distributed.comm.core.CommClosedError: in <closed TCP>: ConnectionResetError: [Errno 104] Connection reset by peer

The above exception was the direct cause of the following exception:

Traceback (most recent call last):
  File "/home/ntolley/anaconda3/envs/sbi/lib/python3.8/site-packages/tornado/ioloop.py", line 741, in _run_callback
    ret = callback()
  File "/home/ntolley/anaconda3/envs/sbi/lib/python3.8/site-packages/tornado/ioloop.py", line 765, in _discard_future_result
    future.result()
  File "/home/ntolley/anaconda3/envs/sbi/lib/python3.8/site-packages/distributed/worker.py", line 976, in heartbeat
    raise e
  File "/home/ntolley/anaconda3/envs/sbi/lib/python3.8/site-packages/distributed/worker.py", line 936, in heartbeat
    response = await retry_operation(
  File "/home/ntolley/anaconda3/envs/sbi/lib/python3.8/site-packages/distributed/utils_comm.py", line 384, in retry_operation
    return await retry(
  File "/home/ntolley/anaconda3/envs/sbi/lib/python3.8/site-packages/distributed/utils_comm.py", line 369, in retry
    return await coro()
  File "/home/ntolley/anaconda3/envs/sbi/lib/python3.8/site-packages/distributed/core.py", line 855, in send_recv_from_rpc
    comm = await self.pool.connect(self.addr)
  File "/home/ntolley/anaconda3/envs/sbi/lib/python3.8/site-packages/distributed/core.py", line 1006, in connect
    comm = await connect(
  File "/home/ntolley/anaconda3/envs/sbi/lib/python3.8/site-packages/distributed/comm/core.py", line 324, in connect
    raise IOError(
OSError: Timed out during handshake while connecting to tcp://198.202.103.184:34547 after 10 s
tornado.application - ERROR - Exception in callback functools.partial(<bound method IOLoop._discard_future_result of <tornado.platform.asyncio.AsyncIOLoop object at 0x1554c9a5baf0>>, <Task finished name='Task-421' coro=<Worker.heartbeat() done, defined at /home/ntolley/anaconda3/envs/sbi/lib/python3.8/site-packages/distributed/worker.py:930> exception=OSError('Timed out during handshake while connecting to tcp://198.202.103.184:34547 after 10 s')>)
Traceback (most recent call last):
  File "/home/ntolley/anaconda3/envs/sbi/lib/python3.8/site-packages/tornado/iostream.py", line 867, in _read_to_buffer
    bytes_read = self.read_from_fd(buf)
  File "/home/ntolley/anaconda3/envs/sbi/lib/python3.8/site-packages/tornado/iostream.py", line 1140, in read_from_fd
    return self.socket.recv_into(buf, len(buf))
ConnectionResetError: [Errno 104] Connection reset by peer

The above exception was the direct cause of the following exception:

Traceback (most recent call last):
  File "/home/ntolley/anaconda3/envs/sbi/lib/python3.8/site-packages/distributed/comm/core.py", line 319, in connect
    handshake = await asyncio.wait_for(comm.read(), time_left())
  File "/home/ntolley/anaconda3/envs/sbi/lib/python3.8/asyncio/tasks.py", line 491, in wait_for
    return fut.result()
  File "/home/ntolley/anaconda3/envs/sbi/lib/python3.8/site-packages/distributed/comm/tcp.py", line 202, in read
    convert_stream_closed_error(self, e)
  File "/home/ntolley/anaconda3/envs/sbi/lib/python3.8/site-packages/distributed/comm/tcp.py", line 122, in convert_stream_closed_error
    raise CommClosedError(
distributed.comm.core.CommClosedError: in <closed TCP>: ConnectionResetError: [Errno 104] Connection reset by peer

The above exception was the direct cause of the following exception:

Traceback (most recent call last):
  File "/home/ntolley/anaconda3/envs/sbi/lib/python3.8/site-packages/tornado/ioloop.py", line 741, in _run_callback
    ret = callback()
  File "/home/ntolley/anaconda3/envs/sbi/lib/python3.8/site-packages/tornado/ioloop.py", line 765, in _discard_future_result
    future.result()
  File "/home/ntolley/anaconda3/envs/sbi/lib/python3.8/site-packages/distributed/worker.py", line 976, in heartbeat
    raise e
  File "/home/ntolley/anaconda3/envs/sbi/lib/python3.8/site-packages/distributed/worker.py", line 936, in heartbeat
    response = await retry_operation(
  File "/home/ntolley/anaconda3/envs/sbi/lib/python3.8/site-packages/distributed/utils_comm.py", line 384, in retry_operation
    return await retry(
  File "/home/ntolley/anaconda3/envs/sbi/lib/python3.8/site-packages/distributed/utils_comm.py", line 369, in retry
    return await coro()
  File "/home/ntolley/anaconda3/envs/sbi/lib/python3.8/site-packages/distributed/core.py", line 855, in send_recv_from_rpc
    comm = await self.pool.connect(self.addr)
  File "/home/ntolley/anaconda3/envs/sbi/lib/python3.8/site-packages/distributed/core.py", line 1006, in connect
    comm = await connect(
  File "/home/ntolley/anaconda3/envs/sbi/lib/python3.8/site-packages/distributed/comm/core.py", line 324, in connect
    raise IOError(
OSError: Timed out during handshake while connecting to tcp://198.202.103.184:34547 after 10 s
tornado.application - ERROR - Exception in callback functools.partial(<bound method IOLoop._discard_future_result of <tornado.platform.asyncio.AsyncIOLoop object at 0x1554c9a5baf0>>, <Task finished name='Task-424' coro=<Worker.heartbeat() done, defined at /home/ntolley/anaconda3/envs/sbi/lib/python3.8/site-packages/distributed/worker.py:930> exception=OSError('Timed out during handshake while connecting to tcp://198.202.103.184:34547 after 10 s')>)
Traceback (most recent call last):
  File "/home/ntolley/anaconda3/envs/sbi/lib/python3.8/site-packages/tornado/iostream.py", line 867, in _read_to_buffer
    bytes_read = self.read_from_fd(buf)
  File "/home/ntolley/anaconda3/envs/sbi/lib/python3.8/site-packages/tornado/iostream.py", line 1140, in read_from_fd
    return self.socket.recv_into(buf, len(buf))
ConnectionResetError: [Errno 104] Connection reset by peer

The above exception was the direct cause of the following exception:

Traceback (most recent call last):
  File "/home/ntolley/anaconda3/envs/sbi/lib/python3.8/site-packages/distributed/comm/core.py", line 319, in connect
    handshake = await asyncio.wait_for(comm.read(), time_left())
  File "/home/ntolley/anaconda3/envs/sbi/lib/python3.8/asyncio/tasks.py", line 491, in wait_for
    return fut.result()
  File "/home/ntolley/anaconda3/envs/sbi/lib/python3.8/site-packages/distributed/comm/tcp.py", line 202, in read
    convert_stream_closed_error(self, e)
  File "/home/ntolley/anaconda3/envs/sbi/lib/python3.8/site-packages/distributed/comm/tcp.py", line 122, in convert_stream_closed_error
    raise CommClosedError(
distributed.comm.core.CommClosedError: in <closed TCP>: ConnectionResetError: [Errno 104] Connection reset by peer

The above exception was the direct cause of the following exception:

Traceback (most recent call last):
  File "/home/ntolley/anaconda3/envs/sbi/lib/python3.8/site-packages/tornado/ioloop.py", line 741, in _run_callback
    ret = callback()
  File "/home/ntolley/anaconda3/envs/sbi/lib/python3.8/site-packages/tornado/ioloop.py", line 765, in _discard_future_result
    future.result()
  File "/home/ntolley/anaconda3/envs/sbi/lib/python3.8/site-packages/distributed/worker.py", line 976, in heartbeat
    raise e
  File "/home/ntolley/anaconda3/envs/sbi/lib/python3.8/site-packages/distributed/worker.py", line 936, in heartbeat
    response = await retry_operation(
  File "/home/ntolley/anaconda3/envs/sbi/lib/python3.8/site-packages/distributed/utils_comm.py", line 384, in retry_operation
    return await retry(
  File "/home/ntolley/anaconda3/envs/sbi/lib/python3.8/site-packages/distributed/utils_comm.py", line 369, in retry
    return await coro()
  File "/home/ntolley/anaconda3/envs/sbi/lib/python3.8/site-packages/distributed/core.py", line 855, in send_recv_from_rpc
    comm = await self.pool.connect(self.addr)
  File "/home/ntolley/anaconda3/envs/sbi/lib/python3.8/site-packages/distributed/core.py", line 1006, in connect
    comm = await connect(
  File "/home/ntolley/anaconda3/envs/sbi/lib/python3.8/site-packages/distributed/comm/core.py", line 324, in connect
    raise IOError(
OSError: Timed out during handshake while connecting to tcp://198.202.103.184:34547 after 10 s
tornado.application - ERROR - Exception in callback functools.partial(<bound method IOLoop._discard_future_result of <tornado.platform.asyncio.AsyncIOLoop object at 0x1554c9a5aaf0>>, <Task finished name='Task-426' coro=<Worker.heartbeat() done, defined at /home/ntolley/anaconda3/envs/sbi/lib/python3.8/site-packages/distributed/worker.py:930> exception=OSError('Timed out during handshake while connecting to tcp://198.202.103.184:34547 after 10 s')>)
Traceback (most recent call last):
  File "/home/ntolley/anaconda3/envs/sbi/lib/python3.8/site-packages/tornado/iostream.py", line 867, in _read_to_buffer
    bytes_read = self.read_from_fd(buf)
  File "/home/ntolley/anaconda3/envs/sbi/lib/python3.8/site-packages/tornado/iostream.py", line 1140, in read_from_fd
    return self.socket.recv_into(buf, len(buf))
ConnectionResetError: [Errno 104] Connection reset by peer

The above exception was the direct cause of the following exception:

Traceback (most recent call last):
  File "/home/ntolley/anaconda3/envs/sbi/lib/python3.8/site-packages/distributed/comm/core.py", line 319, in connect
    handshake = await asyncio.wait_for(comm.read(), time_left())
  File "/home/ntolley/anaconda3/envs/sbi/lib/python3.8/asyncio/tasks.py", line 491, in wait_for
    return fut.result()
  File "/home/ntolley/anaconda3/envs/sbi/lib/python3.8/site-packages/distributed/comm/tcp.py", line 202, in read
    convert_stream_closed_error(self, e)
  File "/home/ntolley/anaconda3/envs/sbi/lib/python3.8/site-packages/distributed/comm/tcp.py", line 122, in convert_stream_closed_error
    raise CommClosedError(
distributed.comm.core.CommClosedError: in <closed TCP>: ConnectionResetError: [Errno 104] Connection reset by peer

The above exception was the direct cause of the following exception:

Traceback (most recent call last):
  File "/home/ntolley/anaconda3/envs/sbi/lib/python3.8/site-packages/tornado/ioloop.py", line 741, in _run_callback
    ret = callback()
  File "/home/ntolley/anaconda3/envs/sbi/lib/python3.8/site-packages/tornado/ioloop.py", line 765, in _discard_future_result
    future.result()
  File "/home/ntolley/anaconda3/envs/sbi/lib/python3.8/site-packages/distributed/worker.py", line 976, in heartbeat
    raise e
  File "/home/ntolley/anaconda3/envs/sbi/lib/python3.8/site-packages/distributed/worker.py", line 936, in heartbeat
    response = await retry_operation(
  File "/home/ntolley/anaconda3/envs/sbi/lib/python3.8/site-packages/distributed/utils_comm.py", line 384, in retry_operation
    return await retry(
  File "/home/ntolley/anaconda3/envs/sbi/lib/python3.8/site-packages/distributed/utils_comm.py", line 369, in retry
    return await coro()
  File "/home/ntolley/anaconda3/envs/sbi/lib/python3.8/site-packages/distributed/core.py", line 855, in send_recv_from_rpc
    comm = await self.pool.connect(self.addr)
  File "/home/ntolley/anaconda3/envs/sbi/lib/python3.8/site-packages/distributed/core.py", line 1006, in connect
    comm = await connect(
  File "/home/ntolley/anaconda3/envs/sbi/lib/python3.8/site-packages/distributed/comm/core.py", line 324, in connect
    raise IOError(
OSError: Timed out during handshake while connecting to tcp://198.202.103.184:34547 after 10 s
tornado.application - ERROR - Exception in callback functools.partial(<bound method IOLoop._discard_future_result of <tornado.platform.asyncio.AsyncIOLoop object at 0x1554c9a5baf0>>, <Task finished name='Task-423' coro=<Worker.heartbeat() done, defined at /home/ntolley/anaconda3/envs/sbi/lib/python3.8/site-packages/distributed/worker.py:930> exception=OSError('Timed out during handshake while connecting to tcp://198.202.103.184:34547 after 10 s')>)
Traceback (most recent call last):
  File "/home/ntolley/anaconda3/envs/sbi/lib/python3.8/site-packages/tornado/iostream.py", line 867, in _read_to_buffer
    bytes_read = self.read_from_fd(buf)
  File "/home/ntolley/anaconda3/envs/sbi/lib/python3.8/site-packages/tornado/iostream.py", line 1140, in read_from_fd
    return self.socket.recv_into(buf, len(buf))
ConnectionResetError: [Errno 104] Connection reset by peer

The above exception was the direct cause of the following exception:

Traceback (most recent call last):
  File "/home/ntolley/anaconda3/envs/sbi/lib/python3.8/site-packages/distributed/comm/core.py", line 319, in connect
    handshake = await asyncio.wait_for(comm.read(), time_left())
  File "/home/ntolley/anaconda3/envs/sbi/lib/python3.8/asyncio/tasks.py", line 491, in wait_for
    return fut.result()
  File "/home/ntolley/anaconda3/envs/sbi/lib/python3.8/site-packages/distributed/comm/tcp.py", line 202, in read
    convert_stream_closed_error(self, e)
  File "/home/ntolley/anaconda3/envs/sbi/lib/python3.8/site-packages/distributed/comm/tcp.py", line 122, in convert_stream_closed_error
    raise CommClosedError(
distributed.comm.core.CommClosedError: in <closed TCP>: ConnectionResetError: [Errno 104] Connection reset by peer

The above exception was the direct cause of the following exception:

Traceback (most recent call last):
  File "/home/ntolley/anaconda3/envs/sbi/lib/python3.8/site-packages/tornado/ioloop.py", line 741, in _run_callback
    ret = callback()
  File "/home/ntolley/anaconda3/envs/sbi/lib/python3.8/site-packages/tornado/ioloop.py", line 765, in _discard_future_result
    future.result()
  File "/home/ntolley/anaconda3/envs/sbi/lib/python3.8/site-packages/distributed/worker.py", line 976, in heartbeat
    raise e
  File "/home/ntolley/anaconda3/envs/sbi/lib/python3.8/site-packages/distributed/worker.py", line 936, in heartbeat
    response = await retry_operation(
  File "/home/ntolley/anaconda3/envs/sbi/lib/python3.8/site-packages/distributed/utils_comm.py", line 384, in retry_operation
    return await retry(
  File "/home/ntolley/anaconda3/envs/sbi/lib/python3.8/site-packages/distributed/utils_comm.py", line 369, in retry
    return await coro()
  File "/home/ntolley/anaconda3/envs/sbi/lib/python3.8/site-packages/distributed/core.py", line 855, in send_recv_from_rpc
    comm = await self.pool.connect(self.addr)
  File "/home/ntolley/anaconda3/envs/sbi/lib/python3.8/site-packages/distributed/core.py", line 1006, in connect
    comm = await connect(
  File "/home/ntolley/anaconda3/envs/sbi/lib/python3.8/site-packages/distributed/comm/core.py", line 324, in connect
    raise IOError(
OSError: Timed out during handshake while connecting to tcp://198.202.103.184:34547 after 10 s
tornado.application - ERROR - Exception in callback functools.partial(<bound method IOLoop._discard_future_result of <tornado.platform.asyncio.AsyncIOLoop object at 0x1554c9a5baf0>>, <Task finished name='Task-409' coro=<Worker.heartbeat() done, defined at /home/ntolley/anaconda3/envs/sbi/lib/python3.8/site-packages/distributed/worker.py:930> exception=OSError('Timed out during handshake while connecting to tcp://198.202.103.184:34547 after 10 s')>)
Traceback (most recent call last):
  File "/home/ntolley/anaconda3/envs/sbi/lib/python3.8/site-packages/tornado/iostream.py", line 867, in _read_to_buffer
    bytes_read = self.read_from_fd(buf)
  File "/home/ntolley/anaconda3/envs/sbi/lib/python3.8/site-packages/tornado/iostream.py", line 1140, in read_from_fd
    return self.socket.recv_into(buf, len(buf))
ConnectionResetError: [Errno 104] Connection reset by peer

The above exception was the direct cause of the following exception:

Traceback (most recent call last):
  File "/home/ntolley/anaconda3/envs/sbi/lib/python3.8/site-packages/distributed/comm/core.py", line 319, in connect
    handshake = await asyncio.wait_for(comm.read(), time_left())
  File "/home/ntolley/anaconda3/envs/sbi/lib/python3.8/asyncio/tasks.py", line 491, in wait_for
    return fut.result()
  File "/home/ntolley/anaconda3/envs/sbi/lib/python3.8/site-packages/distributed/comm/tcp.py", line 202, in read
    convert_stream_closed_error(self, e)
  File "/home/ntolley/anaconda3/envs/sbi/lib/python3.8/site-packages/distributed/comm/tcp.py", line 122, in convert_stream_closed_error
    raise CommClosedError(
distributed.comm.core.CommClosedError: in <closed TCP>: ConnectionResetError: [Errno 104] Connection reset by peer

The above exception was the direct cause of the following exception:

Traceback (most recent call last):
  File "/home/ntolley/anaconda3/envs/sbi/lib/python3.8/site-packages/tornado/ioloop.py", line 741, in _run_callback
    ret = callback()
  File "/home/ntolley/anaconda3/envs/sbi/lib/python3.8/site-packages/tornado/ioloop.py", line 765, in _discard_future_result
    future.result()
  File "/home/ntolley/anaconda3/envs/sbi/lib/python3.8/site-packages/distributed/worker.py", line 976, in heartbeat
    raise e
  File "/home/ntolley/anaconda3/envs/sbi/lib/python3.8/site-packages/distributed/worker.py", line 936, in heartbeat
    response = await retry_operation(
  File "/home/ntolley/anaconda3/envs/sbi/lib/python3.8/site-packages/distributed/utils_comm.py", line 384, in retry_operation
    return await retry(
  File "/home/ntolley/anaconda3/envs/sbi/lib/python3.8/site-packages/distributed/utils_comm.py", line 369, in retry
    return await coro()
  File "/home/ntolley/anaconda3/envs/sbi/lib/python3.8/site-packages/distributed/core.py", line 855, in send_recv_from_rpc
    comm = await self.pool.connect(self.addr)
  File "/home/ntolley/anaconda3/envs/sbi/lib/python3.8/site-packages/distributed/core.py", line 1006, in connect
    comm = await connect(
  File "/home/ntolley/anaconda3/envs/sbi/lib/python3.8/site-packages/distributed/comm/core.py", line 324, in connect
    raise IOError(
OSError: Timed out during handshake while connecting to tcp://198.202.103.184:34547 after 10 s
tornado.application - ERROR - Exception in callback functools.partial(<bound method IOLoop._discard_future_result of <tornado.platform.asyncio.AsyncIOLoop object at 0x1554c9a5baf0>>, <Task finished name='Task-428' coro=<Worker.heartbeat() done, defined at /home/ntolley/anaconda3/envs/sbi/lib/python3.8/site-packages/distributed/worker.py:930> exception=OSError('Timed out during handshake while connecting to tcp://198.202.103.184:34547 after 10 s')>)
Traceback (most recent call last):
  File "/home/ntolley/anaconda3/envs/sbi/lib/python3.8/site-packages/tornado/iostream.py", line 867, in _read_to_buffer
    bytes_read = self.read_from_fd(buf)
  File "/home/ntolley/anaconda3/envs/sbi/lib/python3.8/site-packages/tornado/iostream.py", line 1140, in read_from_fd
    return self.socket.recv_into(buf, len(buf))
ConnectionResetError: [Errno 104] Connection reset by peer

The above exception was the direct cause of the following exception:

Traceback (most recent call last):
  File "/home/ntolley/anaconda3/envs/sbi/lib/python3.8/site-packages/distributed/comm/core.py", line 319, in connect
    handshake = await asyncio.wait_for(comm.read(), time_left())
  File "/home/ntolley/anaconda3/envs/sbi/lib/python3.8/asyncio/tasks.py", line 491, in wait_for
    return fut.result()
  File "/home/ntolley/anaconda3/envs/sbi/lib/python3.8/site-packages/distributed/comm/tcp.py", line 202, in read
    convert_stream_closed_error(self, e)
  File "/home/ntolley/anaconda3/envs/sbi/lib/python3.8/site-packages/distributed/comm/tcp.py", line 122, in convert_stream_closed_error
    raise CommClosedError(
distributed.comm.core.CommClosedError: in <closed TCP>: ConnectionResetError: [Errno 104] Connection reset by peer

The above exception was the direct cause of the following exception:

Traceback (most recent call last):
  File "/home/ntolley/anaconda3/envs/sbi/lib/python3.8/site-packages/tornado/ioloop.py", line 741, in _run_callback
    ret = callback()
  File "/home/ntolley/anaconda3/envs/sbi/lib/python3.8/site-packages/tornado/ioloop.py", line 765, in _discard_future_result
    future.result()
  File "/home/ntolley/anaconda3/envs/sbi/lib/python3.8/site-packages/distributed/worker.py", line 976, in heartbeat
    raise e
  File "/home/ntolley/anaconda3/envs/sbi/lib/python3.8/site-packages/distributed/worker.py", line 936, in heartbeat
    response = await retry_operation(
  File "/home/ntolley/anaconda3/envs/sbi/lib/python3.8/site-packages/distributed/utils_comm.py", line 384, in retry_operation
    return await retry(
  File "/home/ntolley/anaconda3/envs/sbi/lib/python3.8/site-packages/distributed/utils_comm.py", line 369, in retry
    return await coro()
  File "/home/ntolley/anaconda3/envs/sbi/lib/python3.8/site-packages/distributed/core.py", line 855, in send_recv_from_rpc
    comm = await self.pool.connect(self.addr)
  File "/home/ntolley/anaconda3/envs/sbi/lib/python3.8/site-packages/distributed/core.py", line 1006, in connect
    comm = await connect(
  File "/home/ntolley/anaconda3/envs/sbi/lib/python3.8/site-packages/distributed/comm/core.py", line 324, in connect
    raise IOError(
OSError: Timed out during handshake while connecting to tcp://198.202.103.184:34547 after 10 s
tornado.application - ERROR - Exception in callback functools.partial(<bound method IOLoop._discard_future_result of <tornado.platform.asyncio.AsyncIOLoop object at 0x1554c9a5baf0>>, <Task finished name='Task-430' coro=<Worker.heartbeat() done, defined at /home/ntolley/anaconda3/envs/sbi/lib/python3.8/site-packages/distributed/worker.py:930> exception=OSError('Timed out during handshake while connecting to tcp://198.202.103.184:34547 after 10 s')>)
Traceback (most recent call last):
  File "/home/ntolley/anaconda3/envs/sbi/lib/python3.8/site-packages/tornado/iostream.py", line 867, in _read_to_buffer
    bytes_read = self.read_from_fd(buf)
  File "/home/ntolley/anaconda3/envs/sbi/lib/python3.8/site-packages/tornado/iostream.py", line 1140, in read_from_fd
    return self.socket.recv_into(buf, len(buf))
ConnectionResetError: [Errno 104] Connection reset by peer

The above exception was the direct cause of the following exception:

Traceback (most recent call last):
  File "/home/ntolley/anaconda3/envs/sbi/lib/python3.8/site-packages/distributed/comm/core.py", line 319, in connect
    handshake = await asyncio.wait_for(comm.read(), time_left())
  File "/home/ntolley/anaconda3/envs/sbi/lib/python3.8/asyncio/tasks.py", line 491, in wait_for
    return fut.result()
  File "/home/ntolley/anaconda3/envs/sbi/lib/python3.8/site-packages/distributed/comm/tcp.py", line 202, in read
    convert_stream_closed_error(self, e)
  File "/home/ntolley/anaconda3/envs/sbi/lib/python3.8/site-packages/distributed/comm/tcp.py", line 122, in convert_stream_closed_error
    raise CommClosedError(
distributed.comm.core.CommClosedError: in <closed TCP>: ConnectionResetError: [Errno 104] Connection reset by peer

The above exception was the direct cause of the following exception:

Traceback (most recent call last):
  File "/home/ntolley/anaconda3/envs/sbi/lib/python3.8/site-packages/tornado/ioloop.py", line 741, in _run_callback
    ret = callback()
  File "/home/ntolley/anaconda3/envs/sbi/lib/python3.8/site-packages/tornado/ioloop.py", line 765, in _discard_future_result
    future.result()
  File "/home/ntolley/anaconda3/envs/sbi/lib/python3.8/site-packages/distributed/worker.py", line 976, in heartbeat
    raise e
  File "/home/ntolley/anaconda3/envs/sbi/lib/python3.8/site-packages/distributed/worker.py", line 936, in heartbeat
    response = await retry_operation(
  File "/home/ntolley/anaconda3/envs/sbi/lib/python3.8/site-packages/distributed/utils_comm.py", line 384, in retry_operation
    return await retry(
  File "/home/ntolley/anaconda3/envs/sbi/lib/python3.8/site-packages/distributed/utils_comm.py", line 369, in retry
    return await coro()
  File "/home/ntolley/anaconda3/envs/sbi/lib/python3.8/site-packages/distributed/core.py", line 855, in send_recv_from_rpc
    comm = await self.pool.connect(self.addr)
  File "/home/ntolley/anaconda3/envs/sbi/lib/python3.8/site-packages/distributed/core.py", line 1006, in connect
    comm = await connect(
  File "/home/ntolley/anaconda3/envs/sbi/lib/python3.8/site-packages/distributed/comm/core.py", line 324, in connect
    raise IOError(
OSError: Timed out during handshake while connecting to tcp://198.202.103.184:34547 after 10 s
tornado.application - ERROR - Exception in callback functools.partial(<bound method IOLoop._discard_future_result of <tornado.platform.asyncio.AsyncIOLoop object at 0x1554c9a5baf0>>, <Task finished name='Task-420' coro=<Worker.heartbeat() done, defined at /home/ntolley/anaconda3/envs/sbi/lib/python3.8/site-packages/distributed/worker.py:930> exception=OSError('Timed out during handshake while connecting to tcp://198.202.103.184:34547 after 10 s')>)
Traceback (most recent call last):
  File "/home/ntolley/anaconda3/envs/sbi/lib/python3.8/site-packages/tornado/iostream.py", line 867, in _read_to_buffer
    bytes_read = self.read_from_fd(buf)
  File "/home/ntolley/anaconda3/envs/sbi/lib/python3.8/site-packages/tornado/iostream.py", line 1140, in read_from_fd
    return self.socket.recv_into(buf, len(buf))
ConnectionResetError: [Errno 104] Connection reset by peer

The above exception was the direct cause of the following exception:

Traceback (most recent call last):
  File "/home/ntolley/anaconda3/envs/sbi/lib/python3.8/site-packages/distributed/comm/core.py", line 319, in connect
    handshake = await asyncio.wait_for(comm.read(), time_left())
  File "/home/ntolley/anaconda3/envs/sbi/lib/python3.8/asyncio/tasks.py", line 491, in wait_for
    return fut.result()
  File "/home/ntolley/anaconda3/envs/sbi/lib/python3.8/site-packages/distributed/comm/tcp.py", line 202, in read
    convert_stream_closed_error(self, e)
  File "/home/ntolley/anaconda3/envs/sbi/lib/python3.8/site-packages/distributed/comm/tcp.py", line 122, in convert_stream_closed_error
    raise CommClosedError(
distributed.comm.core.CommClosedError: in <closed TCP>: ConnectionResetError: [Errno 104] Connection reset by peer

The above exception was the direct cause of the following exception:

Traceback (most recent call last):
  File "/home/ntolley/anaconda3/envs/sbi/lib/python3.8/site-packages/tornado/ioloop.py", line 741, in _run_callback
    ret = callback()
  File "/home/ntolley/anaconda3/envs/sbi/lib/python3.8/site-packages/tornado/ioloop.py", line 765, in _discard_future_result
    future.result()
  File "/home/ntolley/anaconda3/envs/sbi/lib/python3.8/site-packages/distributed/worker.py", line 976, in heartbeat
    raise e
  File "/home/ntolley/anaconda3/envs/sbi/lib/python3.8/site-packages/distributed/worker.py", line 936, in heartbeat
    response = await retry_operation(
  File "/home/ntolley/anaconda3/envs/sbi/lib/python3.8/site-packages/distributed/utils_comm.py", line 384, in retry_operation
    return await retry(
  File "/home/ntolley/anaconda3/envs/sbi/lib/python3.8/site-packages/distributed/utils_comm.py", line 369, in retry
    return await coro()
  File "/home/ntolley/anaconda3/envs/sbi/lib/python3.8/site-packages/distributed/core.py", line 855, in send_recv_from_rpc
    comm = await self.pool.connect(self.addr)
  File "/home/ntolley/anaconda3/envs/sbi/lib/python3.8/site-packages/distributed/core.py", line 1006, in connect
    comm = await connect(
  File "/home/ntolley/anaconda3/envs/sbi/lib/python3.8/site-packages/distributed/comm/core.py", line 324, in connect
    raise IOError(
OSError: Timed out during handshake while connecting to tcp://198.202.103.184:34547 after 10 s
tornado.application - ERROR - Exception in callback functools.partial(<bound method IOLoop._discard_future_result of <tornado.platform.asyncio.AsyncIOLoop object at 0x1554c9a5baf0>>, <Task finished name='Task-425' coro=<Worker.heartbeat() done, defined at /home/ntolley/anaconda3/envs/sbi/lib/python3.8/site-packages/distributed/worker.py:930> exception=OSError('Timed out during handshake while connecting to tcp://198.202.103.184:34547 after 10 s')>)
Traceback (most recent call last):
  File "/home/ntolley/anaconda3/envs/sbi/lib/python3.8/site-packages/tornado/iostream.py", line 867, in _read_to_buffer
    bytes_read = self.read_from_fd(buf)
  File "/home/ntolley/anaconda3/envs/sbi/lib/python3.8/site-packages/tornado/iostream.py", line 1140, in read_from_fd
    return self.socket.recv_into(buf, len(buf))
ConnectionResetError: [Errno 104] Connection reset by peer

The above exception was the direct cause of the following exception:

Traceback (most recent call last):
  File "/home/ntolley/anaconda3/envs/sbi/lib/python3.8/site-packages/distributed/comm/core.py", line 319, in connect
    handshake = await asyncio.wait_for(comm.read(), time_left())
  File "/home/ntolley/anaconda3/envs/sbi/lib/python3.8/asyncio/tasks.py", line 491, in wait_for
    return fut.result()
  File "/home/ntolley/anaconda3/envs/sbi/lib/python3.8/site-packages/distributed/comm/tcp.py", line 202, in read
    convert_stream_closed_error(self, e)
  File "/home/ntolley/anaconda3/envs/sbi/lib/python3.8/site-packages/distributed/comm/tcp.py", line 122, in convert_stream_closed_error
    raise CommClosedError(
distributed.comm.core.CommClosedError: in <closed TCP>: ConnectionResetError: [Errno 104] Connection reset by peer

The above exception was the direct cause of the following exception:

Traceback (most recent call last):
  File "/home/ntolley/anaconda3/envs/sbi/lib/python3.8/site-packages/tornado/ioloop.py", line 741, in _run_callback
    ret = callback()
  File "/home/ntolley/anaconda3/envs/sbi/lib/python3.8/site-packages/tornado/ioloop.py", line 765, in _discard_future_result
    future.result()
  File "/home/ntolley/anaconda3/envs/sbi/lib/python3.8/site-packages/distributed/worker.py", line 976, in heartbeat
    raise e
  File "/home/ntolley/anaconda3/envs/sbi/lib/python3.8/site-packages/distributed/worker.py", line 936, in heartbeat
    response = await retry_operation(
  File "/home/ntolley/anaconda3/envs/sbi/lib/python3.8/site-packages/distributed/utils_comm.py", line 384, in retry_operation
    return await retry(
  File "/home/ntolley/anaconda3/envs/sbi/lib/python3.8/site-packages/distributed/utils_comm.py", line 369, in retry
    return await coro()
  File "/home/ntolley/anaconda3/envs/sbi/lib/python3.8/site-packages/distributed/core.py", line 855, in send_recv_from_rpc
    comm = await self.pool.connect(self.addr)
  File "/home/ntolley/anaconda3/envs/sbi/lib/python3.8/site-packages/distributed/core.py", line 1006, in connect
    comm = await connect(
  File "/home/ntolley/anaconda3/envs/sbi/lib/python3.8/site-packages/distributed/comm/core.py", line 324, in connect
    raise IOError(
OSError: Timed out during handshake while connecting to tcp://198.202.103.184:34547 after 10 s
tornado.application - ERROR - Exception in callback functools.partial(<bound method IOLoop._discard_future_result of <tornado.platform.asyncio.AsyncIOLoop object at 0x1554c9a5baf0>>, <Task finished name='Task-420' coro=<Worker.heartbeat() done, defined at /home/ntolley/anaconda3/envs/sbi/lib/python3.8/site-packages/distributed/worker.py:930> exception=OSError('Timed out during handshake while connecting to tcp://198.202.103.184:34547 after 10 s')>)
Traceback (most recent call last):
  File "/home/ntolley/anaconda3/envs/sbi/lib/python3.8/site-packages/tornado/iostream.py", line 867, in _read_to_buffer
    bytes_read = self.read_from_fd(buf)
  File "/home/ntolley/anaconda3/envs/sbi/lib/python3.8/site-packages/tornado/iostream.py", line 1140, in read_from_fd
    return self.socket.recv_into(buf, len(buf))
ConnectionResetError: [Errno 104] Connection reset by peer

The above exception was the direct cause of the following exception:

Traceback (most recent call last):
  File "/home/ntolley/anaconda3/envs/sbi/lib/python3.8/site-packages/distributed/comm/core.py", line 319, in connect
    handshake = await asyncio.wait_for(comm.read(), time_left())
  File "/home/ntolley/anaconda3/envs/sbi/lib/python3.8/asyncio/tasks.py", line 491, in wait_for
    return fut.result()
  File "/home/ntolley/anaconda3/envs/sbi/lib/python3.8/site-packages/distributed/comm/tcp.py", line 202, in read
    convert_stream_closed_error(self, e)
  File "/home/ntolley/anaconda3/envs/sbi/lib/python3.8/site-packages/distributed/comm/tcp.py", line 122, in convert_stream_closed_error
    raise CommClosedError(
distributed.comm.core.CommClosedError: in <closed TCP>: ConnectionResetError: [Errno 104] Connection reset by peer

The above exception was the direct cause of the following exception:

Traceback (most recent call last):
  File "/home/ntolley/anaconda3/envs/sbi/lib/python3.8/site-packages/tornado/ioloop.py", line 741, in _run_callback
    ret = callback()
  File "/home/ntolley/anaconda3/envs/sbi/lib/python3.8/site-packages/tornado/ioloop.py", line 765, in _discard_future_result
    future.result()
  File "/home/ntolley/anaconda3/envs/sbi/lib/python3.8/site-packages/distributed/worker.py", line 976, in heartbeat
    raise e
  File "/home/ntolley/anaconda3/envs/sbi/lib/python3.8/site-packages/distributed/worker.py", line 936, in heartbeat
    response = await retry_operation(
  File "/home/ntolley/anaconda3/envs/sbi/lib/python3.8/site-packages/distributed/utils_comm.py", line 384, in retry_operation
    return await retry(
  File "/home/ntolley/anaconda3/envs/sbi/lib/python3.8/site-packages/distributed/utils_comm.py", line 369, in retry
    return await coro()
  File "/home/ntolley/anaconda3/envs/sbi/lib/python3.8/site-packages/distributed/core.py", line 855, in send_recv_from_rpc
    comm = await self.pool.connect(self.addr)
  File "/home/ntolley/anaconda3/envs/sbi/lib/python3.8/site-packages/distributed/core.py", line 1006, in connect
    comm = await connect(
  File "/home/ntolley/anaconda3/envs/sbi/lib/python3.8/site-packages/distributed/comm/core.py", line 324, in connect
    raise IOError(
OSError: Timed out during handshake while connecting to tcp://198.202.103.184:34547 after 10 s
tornado.application - ERROR - Exception in callback functools.partial(<bound method IOLoop._discard_future_result of <tornado.platform.asyncio.AsyncIOLoop object at 0x1554c9a5baf0>>, <Task finished name='Task-423' coro=<Worker.heartbeat() done, defined at /home/ntolley/anaconda3/envs/sbi/lib/python3.8/site-packages/distributed/worker.py:930> exception=OSError('Timed out during handshake while connecting to tcp://198.202.103.184:34547 after 10 s')>)
Traceback (most recent call last):
  File "/home/ntolley/anaconda3/envs/sbi/lib/python3.8/site-packages/tornado/iostream.py", line 867, in _read_to_buffer
    bytes_read = self.read_from_fd(buf)
  File "/home/ntolley/anaconda3/envs/sbi/lib/python3.8/site-packages/tornado/iostream.py", line 1140, in read_from_fd
    return self.socket.recv_into(buf, len(buf))
ConnectionResetError: [Errno 104] Connection reset by peer

The above exception was the direct cause of the following exception:

Traceback (most recent call last):
  File "/home/ntolley/anaconda3/envs/sbi/lib/python3.8/site-packages/distributed/comm/core.py", line 319, in connect
    handshake = await asyncio.wait_for(comm.read(), time_left())
  File "/home/ntolley/anaconda3/envs/sbi/lib/python3.8/asyncio/tasks.py", line 491, in wait_for
    return fut.result()
  File "/home/ntolley/anaconda3/envs/sbi/lib/python3.8/site-packages/distributed/comm/tcp.py", line 202, in read
    convert_stream_closed_error(self, e)
  File "/home/ntolley/anaconda3/envs/sbi/lib/python3.8/site-packages/distributed/comm/tcp.py", line 122, in convert_stream_closed_error
    raise CommClosedError(
distributed.comm.core.CommClosedError: in <closed TCP>: ConnectionResetError: [Errno 104] Connection reset by peer

The above exception was the direct cause of the following exception:

Traceback (most recent call last):
  File "/home/ntolley/anaconda3/envs/sbi/lib/python3.8/site-packages/tornado/ioloop.py", line 741, in _run_callback
    ret = callback()
  File "/home/ntolley/anaconda3/envs/sbi/lib/python3.8/site-packages/tornado/ioloop.py", line 765, in _discard_future_result
    future.result()
  File "/home/ntolley/anaconda3/envs/sbi/lib/python3.8/site-packages/distributed/worker.py", line 976, in heartbeat
    raise e
  File "/home/ntolley/anaconda3/envs/sbi/lib/python3.8/site-packages/distributed/worker.py", line 936, in heartbeat
    response = await retry_operation(
  File "/home/ntolley/anaconda3/envs/sbi/lib/python3.8/site-packages/distributed/utils_comm.py", line 384, in retry_operation
    return await retry(
  File "/home/ntolley/anaconda3/envs/sbi/lib/python3.8/site-packages/distributed/utils_comm.py", line 369, in retry
    return await coro()
  File "/home/ntolley/anaconda3/envs/sbi/lib/python3.8/site-packages/distributed/core.py", line 855, in send_recv_from_rpc
    comm = await self.pool.connect(self.addr)
  File "/home/ntolley/anaconda3/envs/sbi/lib/python3.8/site-packages/distributed/core.py", line 1006, in connect
    comm = await connect(
  File "/home/ntolley/anaconda3/envs/sbi/lib/python3.8/site-packages/distributed/comm/core.py", line 324, in connect
    raise IOError(
OSError: Timed out during handshake while connecting to tcp://198.202.103.184:34547 after 10 s
tornado.application - ERROR - Exception in callback functools.partial(<bound method IOLoop._discard_future_result of <tornado.platform.asyncio.AsyncIOLoop object at 0x1554c9a5baf0>>, <Task finished name='Task-426' coro=<Worker.heartbeat() done, defined at /home/ntolley/anaconda3/envs/sbi/lib/python3.8/site-packages/distributed/worker.py:930> exception=OSError('Timed out during handshake while connecting to tcp://198.202.103.184:34547 after 10 s')>)
Traceback (most recent call last):
  File "/home/ntolley/anaconda3/envs/sbi/lib/python3.8/site-packages/tornado/iostream.py", line 867, in _read_to_buffer
    bytes_read = self.read_from_fd(buf)
  File "/home/ntolley/anaconda3/envs/sbi/lib/python3.8/site-packages/tornado/iostream.py", line 1140, in read_from_fd
    return self.socket.recv_into(buf, len(buf))
ConnectionResetError: [Errno 104] Connection reset by peer

The above exception was the direct cause of the following exception:

Traceback (most recent call last):
  File "/home/ntolley/anaconda3/envs/sbi/lib/python3.8/site-packages/distributed/comm/core.py", line 319, in connect
    handshake = await asyncio.wait_for(comm.read(), time_left())
  File "/home/ntolley/anaconda3/envs/sbi/lib/python3.8/asyncio/tasks.py", line 491, in wait_for
    return fut.result()
  File "/home/ntolley/anaconda3/envs/sbi/lib/python3.8/site-packages/distributed/comm/tcp.py", line 202, in read
    convert_stream_closed_error(self, e)
  File "/home/ntolley/anaconda3/envs/sbi/lib/python3.8/site-packages/distributed/comm/tcp.py", line 122, in convert_stream_closed_error
    raise CommClosedError(
distributed.comm.core.CommClosedError: in <closed TCP>: ConnectionResetError: [Errno 104] Connection reset by peer

The above exception was the direct cause of the following exception:

Traceback (most recent call last):
  File "/home/ntolley/anaconda3/envs/sbi/lib/python3.8/site-packages/tornado/ioloop.py", line 741, in _run_callback
    ret = callback()
  File "/home/ntolley/anaconda3/envs/sbi/lib/python3.8/site-packages/tornado/ioloop.py", line 765, in _discard_future_result
    future.result()
  File "/home/ntolley/anaconda3/envs/sbi/lib/python3.8/site-packages/distributed/worker.py", line 976, in heartbeat
    raise e
  File "/home/ntolley/anaconda3/envs/sbi/lib/python3.8/site-packages/distributed/worker.py", line 936, in heartbeat
    response = await retry_operation(
  File "/home/ntolley/anaconda3/envs/sbi/lib/python3.8/site-packages/distributed/utils_comm.py", line 384, in retry_operation
    return await retry(
  File "/home/ntolley/anaconda3/envs/sbi/lib/python3.8/site-packages/distributed/utils_comm.py", line 369, in retry
    return await coro()
  File "/home/ntolley/anaconda3/envs/sbi/lib/python3.8/site-packages/distributed/core.py", line 855, in send_recv_from_rpc
    comm = await self.pool.connect(self.addr)
  File "/home/ntolley/anaconda3/envs/sbi/lib/python3.8/site-packages/distributed/core.py", line 1006, in connect
    comm = await connect(
  File "/home/ntolley/anaconda3/envs/sbi/lib/python3.8/site-packages/distributed/comm/core.py", line 324, in connect
    raise IOError(
OSError: Timed out during handshake while connecting to tcp://198.202.103.184:34547 after 10 s
tornado.application - ERROR - Exception in callback functools.partial(<bound method IOLoop._discard_future_result of <tornado.platform.asyncio.AsyncIOLoop object at 0x1554c9a5baf0>>, <Task finished name='Task-426' coro=<Worker.heartbeat() done, defined at /home/ntolley/anaconda3/envs/sbi/lib/python3.8/site-packages/distributed/worker.py:930> exception=OSError('Timed out during handshake while connecting to tcp://198.202.103.184:34547 after 10 s')>)
Traceback (most recent call last):
  File "/home/ntolley/anaconda3/envs/sbi/lib/python3.8/site-packages/tornado/iostream.py", line 867, in _read_to_buffer
    bytes_read = self.read_from_fd(buf)
  File "/home/ntolley/anaconda3/envs/sbi/lib/python3.8/site-packages/tornado/iostream.py", line 1140, in read_from_fd
    return self.socket.recv_into(buf, len(buf))
ConnectionResetError: [Errno 104] Connection reset by peer

The above exception was the direct cause of the following exception:

Traceback (most recent call last):
  File "/home/ntolley/anaconda3/envs/sbi/lib/python3.8/site-packages/distributed/comm/core.py", line 319, in connect
    handshake = await asyncio.wait_for(comm.read(), time_left())
  File "/home/ntolley/anaconda3/envs/sbi/lib/python3.8/asyncio/tasks.py", line 491, in wait_for
    return fut.result()
  File "/home/ntolley/anaconda3/envs/sbi/lib/python3.8/site-packages/distributed/comm/tcp.py", line 202, in read
    convert_stream_closed_error(self, e)
  File "/home/ntolley/anaconda3/envs/sbi/lib/python3.8/site-packages/distributed/comm/tcp.py", line 122, in convert_stream_closed_error
    raise CommClosedError(
distributed.comm.core.CommClosedError: in <closed TCP>: ConnectionResetError: [Errno 104] Connection reset by peer

The above exception was the direct cause of the following exception:

Traceback (most recent call last):
  File "/home/ntolley/anaconda3/envs/sbi/lib/python3.8/site-packages/tornado/ioloop.py", line 741, in _run_callback
    ret = callback()
  File "/home/ntolley/anaconda3/envs/sbi/lib/python3.8/site-packages/tornado/ioloop.py", line 765, in _discard_future_result
    future.result()
  File "/home/ntolley/anaconda3/envs/sbi/lib/python3.8/site-packages/distributed/worker.py", line 976, in heartbeat
    raise e
  File "/home/ntolley/anaconda3/envs/sbi/lib/python3.8/site-packages/distributed/worker.py", line 936, in heartbeat
    response = await retry_operation(
  File "/home/ntolley/anaconda3/envs/sbi/lib/python3.8/site-packages/distributed/utils_comm.py", line 384, in retry_operation
    return await retry(
  File "/home/ntolley/anaconda3/envs/sbi/lib/python3.8/site-packages/distributed/utils_comm.py", line 369, in retry
    return await coro()
  File "/home/ntolley/anaconda3/envs/sbi/lib/python3.8/site-packages/distributed/core.py", line 855, in send_recv_from_rpc
    comm = await self.pool.connect(self.addr)
  File "/home/ntolley/anaconda3/envs/sbi/lib/python3.8/site-packages/distributed/core.py", line 1006, in connect
    comm = await connect(
  File "/home/ntolley/anaconda3/envs/sbi/lib/python3.8/site-packages/distributed/comm/core.py", line 324, in connect
    raise IOError(
OSError: Timed out during handshake while connecting to tcp://198.202.103.184:34547 after 10 s
tornado.application - ERROR - Exception in callback functools.partial(<bound method IOLoop._discard_future_result of <tornado.platform.asyncio.AsyncIOLoop object at 0x1554c9a5baf0>>, <Task finished name='Task-409' coro=<Worker.heartbeat() done, defined at /home/ntolley/anaconda3/envs/sbi/lib/python3.8/site-packages/distributed/worker.py:930> exception=OSError('Timed out during handshake while connecting to tcp://198.202.103.184:34547 after 10 s')>)
Traceback (most recent call last):
  File "/home/ntolley/anaconda3/envs/sbi/lib/python3.8/site-packages/tornado/iostream.py", line 867, in _read_to_buffer
    bytes_read = self.read_from_fd(buf)
  File "/home/ntolley/anaconda3/envs/sbi/lib/python3.8/site-packages/tornado/iostream.py", line 1140, in read_from_fd
    return self.socket.recv_into(buf, len(buf))
ConnectionResetError: [Errno 104] Connection reset by peer

The above exception was the direct cause of the following exception:

Traceback (most recent call last):
  File "/home/ntolley/anaconda3/envs/sbi/lib/python3.8/site-packages/distributed/comm/core.py", line 319, in connect
    handshake = await asyncio.wait_for(comm.read(), time_left())
  File "/home/ntolley/anaconda3/envs/sbi/lib/python3.8/asyncio/tasks.py", line 491, in wait_for
    return fut.result()
  File "/home/ntolley/anaconda3/envs/sbi/lib/python3.8/site-packages/distributed/comm/tcp.py", line 202, in read
    convert_stream_closed_error(self, e)
  File "/home/ntolley/anaconda3/envs/sbi/lib/python3.8/site-packages/distributed/comm/tcp.py", line 122, in convert_stream_closed_error
    raise CommClosedError(
distributed.comm.core.CommClosedError: in <closed TCP>: ConnectionResetError: [Errno 104] Connection reset by peer

The above exception was the direct cause of the following exception:

Traceback (most recent call last):
  File "/home/ntolley/anaconda3/envs/sbi/lib/python3.8/site-packages/tornado/ioloop.py", line 741, in _run_callback
    ret = callback()
  File "/home/ntolley/anaconda3/envs/sbi/lib/python3.8/site-packages/tornado/ioloop.py", line 765, in _discard_future_result
    future.result()
  File "/home/ntolley/anaconda3/envs/sbi/lib/python3.8/site-packages/distributed/worker.py", line 976, in heartbeat
    raise e
  File "/home/ntolley/anaconda3/envs/sbi/lib/python3.8/site-packages/distributed/worker.py", line 936, in heartbeat
    response = await retry_operation(
  File "/home/ntolley/anaconda3/envs/sbi/lib/python3.8/site-packages/distributed/utils_comm.py", line 384, in retry_operation
    return await retry(
  File "/home/ntolley/anaconda3/envs/sbi/lib/python3.8/site-packages/distributed/utils_comm.py", line 369, in retry
    return await coro()
  File "/home/ntolley/anaconda3/envs/sbi/lib/python3.8/site-packages/distributed/core.py", line 855, in send_recv_from_rpc
    comm = await self.pool.connect(self.addr)
  File "/home/ntolley/anaconda3/envs/sbi/lib/python3.8/site-packages/distributed/core.py", line 1006, in connect
    comm = await connect(
  File "/home/ntolley/anaconda3/envs/sbi/lib/python3.8/site-packages/distributed/comm/core.py", line 324, in connect
    raise IOError(
OSError: Timed out during handshake while connecting to tcp://198.202.103.184:34547 after 10 s
distributed.worker - INFO - Stopping worker at tcp://198.202.101.9:39737
distributed.worker - INFO - Stopping worker at tcp://198.202.101.9:41323
distributed.worker - INFO - Stopping worker at tcp://198.202.101.9:46179
distributed.worker - INFO - Stopping worker at tcp://198.202.101.9:35579
distributed.worker - INFO - Stopping worker at tcp://198.202.101.9:42731
distributed.worker - INFO - Stopping worker at tcp://198.202.101.9:35459
distributed.worker - INFO - Stopping worker at tcp://198.202.101.9:38601
distributed.worker - INFO - Stopping worker at tcp://198.202.101.9:39931
distributed.worker - INFO - Stopping worker at tcp://198.202.101.9:36043
distributed.worker - INFO - Stopping worker at tcp://198.202.101.9:42739
distributed.worker - INFO - Stopping worker at tcp://198.202.101.9:33319
distributed.worker - INFO - Stopping worker at tcp://198.202.101.9:34995
distributed.worker - INFO - Stopping worker at tcp://198.202.101.9:43323
distributed.worker - INFO - Stopping worker at tcp://198.202.101.9:38135
distributed.worker - INFO - Stopping worker at tcp://198.202.101.9:33895
distributed.worker - INFO - Stopping worker at tcp://198.202.101.9:36945
tornado.application - ERROR - Exception in callback functools.partial(<bound method IOLoop._discard_future_result of <tornado.platform.asyncio.AsyncIOLoop object at 0x1554c9a5bb20>>, <Task finished name='Task-424' coro=<Worker.heartbeat() done, defined at /home/ntolley/anaconda3/envs/sbi/lib/python3.8/site-packages/distributed/worker.py:930> exception=OSError('Timed out during handshake while connecting to tcp://198.202.103.184:34547 after 10 s')>)
Traceback (most recent call last):
  File "/home/ntolley/anaconda3/envs/sbi/lib/python3.8/site-packages/distributed/comm/core.py", line 319, in connect
    handshake = await asyncio.wait_for(comm.read(), time_left())
  File "/home/ntolley/anaconda3/envs/sbi/lib/python3.8/asyncio/tasks.py", line 498, in wait_for
    raise exceptions.TimeoutError()
asyncio.exceptions.TimeoutError

The above exception was the direct cause of the following exception:

Traceback (most recent call last):
  File "/home/ntolley/anaconda3/envs/sbi/lib/python3.8/site-packages/tornado/ioloop.py", line 741, in _run_callback
    ret = callback()
  File "/home/ntolley/anaconda3/envs/sbi/lib/python3.8/site-packages/tornado/ioloop.py", line 765, in _discard_future_result
    future.result()
  File "/home/ntolley/anaconda3/envs/sbi/lib/python3.8/site-packages/distributed/worker.py", line 976, in heartbeat
    raise e
  File "/home/ntolley/anaconda3/envs/sbi/lib/python3.8/site-packages/distributed/worker.py", line 936, in heartbeat
    response = await retry_operation(
  File "/home/ntolley/anaconda3/envs/sbi/lib/python3.8/site-packages/distributed/utils_comm.py", line 384, in retry_operation
    return await retry(
  File "/home/ntolley/anaconda3/envs/sbi/lib/python3.8/site-packages/distributed/utils_comm.py", line 369, in retry
    return await coro()
  File "/home/ntolley/anaconda3/envs/sbi/lib/python3.8/site-packages/distributed/core.py", line 855, in send_recv_from_rpc
    comm = await self.pool.connect(self.addr)
  File "/home/ntolley/anaconda3/envs/sbi/lib/python3.8/site-packages/distributed/core.py", line 1006, in connect
    comm = await connect(
  File "/home/ntolley/anaconda3/envs/sbi/lib/python3.8/site-packages/distributed/comm/core.py", line 324, in connect
    raise IOError(
OSError: Timed out during handshake while connecting to tcp://198.202.103.184:34547 after 10 s
distributed.worker - INFO - Stopping worker at tcp://198.202.101.9:32945
distributed.worker - INFO - Stopping worker at tcp://198.202.101.9:45597
distributed.worker - INFO - Stopping worker at tcp://198.202.101.9:40983
distributed.worker - INFO - Stopping worker at tcp://198.202.101.9:32867
distributed.worker - INFO - Stopping worker at tcp://198.202.101.9:39333
distributed.worker - INFO - Stopping worker at tcp://198.202.101.9:37881
distributed.worker - INFO - Stopping worker at tcp://198.202.101.9:38795
distributed.worker - INFO - Stopping worker at tcp://198.202.101.9:41933
distributed.worker - INFO - Stopping worker at tcp://198.202.101.9:36123
distributed.worker - INFO - Stopping worker at tcp://198.202.101.9:44099
distributed.worker - INFO - Stopping worker at tcp://198.202.101.9:38207
distributed.worker - INFO - Stopping worker at tcp://198.202.101.9:39727
distributed.worker - INFO - Stopping worker at tcp://198.202.101.9:45049
distributed.worker - INFO - Stopping worker at tcp://198.202.101.9:38621
distributed.worker - INFO - Stopping worker at tcp://198.202.101.9:35881
distributed.worker - INFO - Stopping worker at tcp://198.202.101.9:44621
distributed.worker - INFO - Stopping worker at tcp://198.202.101.9:41783
distributed.worker - INFO - Stopping worker at tcp://198.202.101.9:41005
distributed.worker - INFO - Stopping worker at tcp://198.202.101.9:44989
distributed.worker - INFO - Stopping worker at tcp://198.202.101.9:41883
distributed.nanny - INFO - Worker closed
distributed.nanny - INFO - Worker closed
distributed.nanny - INFO - Worker closed
distributed.nanny - INFO - Worker closed
distributed.nanny - INFO - Worker closed
distributed.worker - INFO - Stopping worker at tcp://198.202.101.9:37011
distributed.worker - INFO - Stopping worker at tcp://198.202.101.9:39783
distributed.nanny - INFO - Worker closed
distributed.nanny - INFO - Worker closed
distributed.worker - INFO - Stopping worker at tcp://198.202.101.9:34801
distributed.nanny - INFO - Worker closed
distributed.worker - INFO - Stopping worker at tcp://198.202.101.9:44701
distributed.worker - INFO - Stopping worker at tcp://198.202.101.9:41997
distributed.worker - INFO - Stopping worker at tcp://198.202.101.9:39157
distributed.worker - INFO - Stopping worker at tcp://198.202.101.9:42399
distributed.worker - INFO - Stopping worker at tcp://198.202.101.9:38503
distributed.worker - INFO - Stopping worker at tcp://198.202.101.9:41911
distributed.worker - INFO - Stopping worker at tcp://198.202.101.9:40853
distributed.worker - INFO - Stopping worker at tcp://198.202.101.9:35215
distributed.nanny - INFO - Worker closed
distributed.nanny - INFO - Worker closed
distributed.worker - INFO - Stopping worker at tcp://198.202.101.9:39911
distributed.worker - INFO - Stopping worker at tcp://198.202.101.9:39261
distributed.nanny - INFO - Worker closed
distributed.nanny - INFO - Worker closed
distributed.nanny - INFO - Worker closed
distributed.nanny - INFO - Worker closed
distributed.nanny - INFO - Worker closed
distributed.nanny - INFO - Worker closed
distributed.nanny - INFO - Worker closed
distributed.nanny - INFO - Worker closed
distributed.nanny - INFO - Worker closed
distributed.nanny - INFO - Worker closed
distributed.nanny - INFO - Worker closed
distributed.nanny - INFO - Worker closed
distributed.nanny - INFO - Worker closed
distributed.nanny - INFO - Worker closed
distributed.nanny - INFO - Worker closed
distributed.nanny - INFO - Worker closed
distributed.nanny - INFO - Worker closed
distributed.nanny - INFO - Worker closed
distributed.nanny - INFO - Worker closed
distributed.nanny - INFO - Worker closed
distributed.nanny - INFO - Worker closed
distributed.nanny - INFO - Worker closed
distributed.nanny - INFO - Worker closed
distributed.nanny - INFO - Worker closed
distributed.nanny - INFO - Worker closed
distributed.nanny - INFO - Worker closed
distributed.core - INFO - Event loop was unresponsive in Nanny for 4.68s.  This is often caused by long-running GIL-holding functions or moving large chunks of data. This can cause timeouts and instability.
distributed.core - INFO - Event loop was unresponsive in Nanny for 4.68s.  This is often caused by long-running GIL-holding functions or moving large chunks of data. This can cause timeouts and instability.
distributed.core - INFO - Event loop was unresponsive in Nanny for 4.68s.  This is often caused by long-running GIL-holding functions or moving large chunks of data. This can cause timeouts and instability.
distributed.core - INFO - Event loop was unresponsive in Nanny for 4.68s.  This is often caused by long-running GIL-holding functions or moving large chunks of data. This can cause timeouts and instability.
distributed.core - INFO - Event loop was unresponsive in Nanny for 4.68s.  This is often caused by long-running GIL-holding functions or moving large chunks of data. This can cause timeouts and instability.
distributed.core - INFO - Event loop was unresponsive in Nanny for 4.68s.  This is often caused by long-running GIL-holding functions or moving large chunks of data. This can cause timeouts and instability.
distributed.core - INFO - Event loop was unresponsive in Nanny for 4.68s.  This is often caused by long-running GIL-holding functions or moving large chunks of data. This can cause timeouts and instability.
distributed.core - INFO - Event loop was unresponsive in Nanny for 4.68s.  This is often caused by long-running GIL-holding functions or moving large chunks of data. This can cause timeouts and instability.
distributed.core - INFO - Event loop was unresponsive in Nanny for 4.68s.  This is often caused by long-running GIL-holding functions or moving large chunks of data. This can cause timeouts and instability.
distributed.core - INFO - Event loop was unresponsive in Nanny for 4.68s.  This is often caused by long-running GIL-holding functions or moving large chunks of data. This can cause timeouts and instability.
distributed.core - INFO - Event loop was unresponsive in Nanny for 4.68s.  This is often caused by long-running GIL-holding functions or moving large chunks of data. This can cause timeouts and instability.
distributed.core - INFO - Event loop was unresponsive in Nanny for 4.68s.  This is often caused by long-running GIL-holding functions or moving large chunks of data. This can cause timeouts and instability.
distributed.core - INFO - Event loop was unresponsive in Nanny for 4.68s.  This is often caused by long-running GIL-holding functions or moving large chunks of data. This can cause timeouts and instability.
distributed.core - INFO - Event loop was unresponsive in Nanny for 4.68s.  This is often caused by long-running GIL-holding functions or moving large chunks of data. This can cause timeouts and instability.
distributed.core - INFO - Event loop was unresponsive in Nanny for 4.68s.  This is often caused by long-running GIL-holding functions or moving large chunks of data. This can cause timeouts and instability.
distributed.core - INFO - Event loop was unresponsive in Nanny for 4.68s.  This is often caused by long-running GIL-holding functions or moving large chunks of data. This can cause timeouts and instability.
distributed.core - INFO - Event loop was unresponsive in Nanny for 4.68s.  This is often caused by long-running GIL-holding functions or moving large chunks of data. This can cause timeouts and instability.
distributed.core - INFO - Event loop was unresponsive in Nanny for 4.68s.  This is often caused by long-running GIL-holding functions or moving large chunks of data. This can cause timeouts and instability.
distributed.core - INFO - Event loop was unresponsive in Nanny for 4.68s.  This is often caused by long-running GIL-holding functions or moving large chunks of data. This can cause timeouts and instability.
distributed.core - INFO - Event loop was unresponsive in Nanny for 4.68s.  This is often caused by long-running GIL-holding functions or moving large chunks of data. This can cause timeouts and instability.
distributed.core - INFO - Event loop was unresponsive in Nanny for 4.68s.  This is often caused by long-running GIL-holding functions or moving large chunks of data. This can cause timeouts and instability.
distributed.core - INFO - Event loop was unresponsive in Nanny for 4.68s.  This is often caused by long-running GIL-holding functions or moving large chunks of data. This can cause timeouts and instability.
distributed.core - INFO - Event loop was unresponsive in Nanny for 4.68s.  This is often caused by long-running GIL-holding functions or moving large chunks of data. This can cause timeouts and instability.
distributed.core - INFO - Event loop was unresponsive in Nanny for 4.68s.  This is often caused by long-running GIL-holding functions or moving large chunks of data. This can cause timeouts and instability.
distributed.core - INFO - Event loop was unresponsive in Nanny for 4.68s.  This is often caused by long-running GIL-holding functions or moving large chunks of data. This can cause timeouts and instability.
distributed.core - INFO - Event loop was unresponsive in Nanny for 4.68s.  This is often caused by long-running GIL-holding functions or moving large chunks of data. This can cause timeouts and instability.
distributed.core - INFO - Event loop was unresponsive in Nanny for 4.68s.  This is often caused by long-running GIL-holding functions or moving large chunks of data. This can cause timeouts and instability.
distributed.core - INFO - Event loop was unresponsive in Nanny for 4.68s.  This is often caused by long-running GIL-holding functions or moving large chunks of data. This can cause timeouts and instability.
distributed.core - INFO - Event loop was unresponsive in Nanny for 4.68s.  This is often caused by long-running GIL-holding functions or moving large chunks of data. This can cause timeouts and instability.
distributed.core - INFO - Event loop was unresponsive in Nanny for 4.68s.  This is often caused by long-running GIL-holding functions or moving large chunks of data. This can cause timeouts and instability.
distributed.core - INFO - Event loop was unresponsive in Nanny for 4.68s.  This is often caused by long-running GIL-holding functions or moving large chunks of data. This can cause timeouts and instability.
distributed.core - INFO - Event loop was unresponsive in Nanny for 4.68s.  This is often caused by long-running GIL-holding functions or moving large chunks of data. This can cause timeouts and instability.
distributed.core - INFO - Event loop was unresponsive in Nanny for 4.68s.  This is often caused by long-running GIL-holding functions or moving large chunks of data. This can cause timeouts and instability.
distributed.core - INFO - Event loop was unresponsive in Nanny for 4.68s.  This is often caused by long-running GIL-holding functions or moving large chunks of data. This can cause timeouts and instability.
distributed.core - INFO - Event loop was unresponsive in Nanny for 4.68s.  This is often caused by long-running GIL-holding functions or moving large chunks of data. This can cause timeouts and instability.
distributed.core - INFO - Event loop was unresponsive in Nanny for 4.67s.  This is often caused by long-running GIL-holding functions or moving large chunks of data. This can cause timeouts and instability.
distributed.core - INFO - Event loop was unresponsive in Nanny for 4.67s.  This is often caused by long-running GIL-holding functions or moving large chunks of data. This can cause timeouts and instability.
distributed.core - INFO - Event loop was unresponsive in Nanny for 4.67s.  This is often caused by long-running GIL-holding functions or moving large chunks of data. This can cause timeouts and instability.
distributed.core - INFO - Event loop was unresponsive in Nanny for 4.67s.  This is often caused by long-running GIL-holding functions or moving large chunks of data. This can cause timeouts and instability.
distributed.core - INFO - Event loop was unresponsive in Nanny for 4.67s.  This is often caused by long-running GIL-holding functions or moving large chunks of data. This can cause timeouts and instability.
distributed.core - INFO - Event loop was unresponsive in Nanny for 4.67s.  This is often caused by long-running GIL-holding functions or moving large chunks of data. This can cause timeouts and instability.
distributed.core - INFO - Event loop was unresponsive in Nanny for 4.67s.  This is often caused by long-running GIL-holding functions or moving large chunks of data. This can cause timeouts and instability.
distributed.core - INFO - Event loop was unresponsive in Nanny for 4.67s.  This is often caused by long-running GIL-holding functions or moving large chunks of data. This can cause timeouts and instability.
distributed.core - INFO - Event loop was unresponsive in Nanny for 4.67s.  This is often caused by long-running GIL-holding functions or moving large chunks of data. This can cause timeouts and instability.
distributed.core - INFO - Event loop was unresponsive in Nanny for 4.67s.  This is often caused by long-running GIL-holding functions or moving large chunks of data. This can cause timeouts and instability.
distributed.core - INFO - Event loop was unresponsive in Nanny for 4.67s.  This is often caused by long-running GIL-holding functions or moving large chunks of data. This can cause timeouts and instability.
distributed.core - INFO - Event loop was unresponsive in Nanny for 4.67s.  This is often caused by long-running GIL-holding functions or moving large chunks of data. This can cause timeouts and instability.
distributed.core - INFO - Event loop was unresponsive in Nanny for 4.67s.  This is often caused by long-running GIL-holding functions or moving large chunks of data. This can cause timeouts and instability.
distributed.core - INFO - Event loop was unresponsive in Nanny for 4.67s.  This is often caused by long-running GIL-holding functions or moving large chunks of data. This can cause timeouts and instability.
distributed.core - INFO - Event loop was unresponsive in Nanny for 4.67s.  This is often caused by long-running GIL-holding functions or moving large chunks of data. This can cause timeouts and instability.
distributed.nanny - INFO - Worker closed
distributed.nanny - INFO - Worker closed
distributed.nanny - INFO - Worker closed
distributed.nanny - INFO - Worker closed
distributed.nanny - INFO - Worker closed
distributed.nanny - INFO - Worker closed
distributed.nanny - INFO - Worker closed
distributed.nanny - INFO - Worker closed
distributed.nanny - INFO - Worker closed
distributed.nanny - INFO - Worker closed
distributed.nanny - INFO - Worker closed
distributed.nanny - INFO - Worker closed
distributed.nanny - INFO - Worker closed
distributed.worker - INFO - Stopping worker at tcp://198.202.101.9:42035
distributed.nanny - INFO - Worker closed
distributed.nanny - INFO - Closing Nanny at 'tcp://198.202.101.9:34011'
distributed.nanny - INFO - Closing Nanny at 'tcp://198.202.101.9:42267'
distributed.nanny - INFO - Closing Nanny at 'tcp://198.202.101.9:37885'
distributed.nanny - INFO - Closing Nanny at 'tcp://198.202.101.9:33343'
distributed.nanny - INFO - Closing Nanny at 'tcp://198.202.101.9:40777'
distributed.nanny - INFO - Closing Nanny at 'tcp://198.202.101.9:38683'
distributed.nanny - INFO - Closing Nanny at 'tcp://198.202.101.9:40779'
distributed.nanny - INFO - Closing Nanny at 'tcp://198.202.101.9:37915'
distributed.nanny - INFO - Closing Nanny at 'tcp://198.202.101.9:37949'
distributed.nanny - INFO - Closing Nanny at 'tcp://198.202.101.9:46177'
distributed.nanny - INFO - Closing Nanny at 'tcp://198.202.101.9:34677'
distributed.nanny - INFO - Closing Nanny at 'tcp://198.202.101.9:33295'
distributed.nanny - INFO - Closing Nanny at 'tcp://198.202.101.9:41415'
distributed.nanny - INFO - Closing Nanny at 'tcp://198.202.101.9:39871'
distributed.nanny - INFO - Closing Nanny at 'tcp://198.202.101.9:34455'
distributed.nanny - INFO - Closing Nanny at 'tcp://198.202.101.9:35589'
distributed.nanny - INFO - Closing Nanny at 'tcp://198.202.101.9:37681'
distributed.nanny - INFO - Closing Nanny at 'tcp://198.202.101.9:33429'
distributed.nanny - INFO - Closing Nanny at 'tcp://198.202.101.9:37753'
distributed.nanny - INFO - Closing Nanny at 'tcp://198.202.101.9:46809'
distributed.nanny - INFO - Closing Nanny at 'tcp://198.202.101.9:43041'
distributed.nanny - INFO - Closing Nanny at 'tcp://198.202.101.9:41515'
distributed.nanny - INFO - Closing Nanny at 'tcp://198.202.101.9:37705'
distributed.nanny - INFO - Closing Nanny at 'tcp://198.202.101.9:38515'
distributed.nanny - INFO - Closing Nanny at 'tcp://198.202.101.9:42179'
distributed.nanny - INFO - Closing Nanny at 'tcp://198.202.101.9:41137'
distributed.nanny - INFO - Closing Nanny at 'tcp://198.202.101.9:34255'
distributed.nanny - INFO - Closing Nanny at 'tcp://198.202.101.9:38743'
distributed.nanny - INFO - Closing Nanny at 'tcp://198.202.101.9:46541'
distributed.nanny - INFO - Closing Nanny at 'tcp://198.202.101.9:43363'
distributed.nanny - INFO - Closing Nanny at 'tcp://198.202.101.9:37215'
distributed.nanny - INFO - Closing Nanny at 'tcp://198.202.101.9:43697'
distributed.nanny - INFO - Closing Nanny at 'tcp://198.202.101.9:42913'
distributed.nanny - INFO - Closing Nanny at 'tcp://198.202.101.9:37607'
distributed.nanny - INFO - Closing Nanny at 'tcp://198.202.101.9:44913'
distributed.nanny - INFO - Closing Nanny at 'tcp://198.202.101.9:36323'
distributed.nanny - INFO - Closing Nanny at 'tcp://198.202.101.9:37829'
distributed.nanny - INFO - Closing Nanny at 'tcp://198.202.101.9:36221'
distributed.nanny - INFO - Closing Nanny at 'tcp://198.202.101.9:33897'
distributed.nanny - INFO - Closing Nanny at 'tcp://198.202.101.9:33537'
distributed.nanny - INFO - Closing Nanny at 'tcp://198.202.101.9:41409'
distributed.nanny - INFO - Closing Nanny at 'tcp://198.202.101.9:37217'
distributed.nanny - INFO - Closing Nanny at 'tcp://198.202.101.9:40871'
distributed.nanny - INFO - Closing Nanny at 'tcp://198.202.101.9:38257'
distributed.nanny - INFO - Closing Nanny at 'tcp://198.202.101.9:39317'
distributed.nanny - INFO - Closing Nanny at 'tcp://198.202.101.9:40931'
distributed.nanny - INFO - Closing Nanny at 'tcp://198.202.101.9:45887'
distributed.nanny - INFO - Closing Nanny at 'tcp://198.202.101.9:43467'
distributed.nanny - INFO - Closing Nanny at 'tcp://198.202.101.9:34097'
distributed.nanny - INFO - Closing Nanny at 'tcp://198.202.101.9:38359'
distributed.dask_worker - INFO - End worker
